Workbook

Sheet Summary each location
B2: 5S Check Sheet xxx Branch Compliance Summary
B3: Sl. No. | C3: Champion | D3: Allocated Area | E3: Compliance % (03-Apr-24) | F3: Compliance % (22-Apr-24) | G3: Compliance % (02-May-24) | H3: Compliance % (24-May-24) | I3: Compliance % (05-June-24) | J3: Compliance % (14-June-24) | K3: Compliance % (06-July-24) | L3: Compliance % (17-July-24) | M3: Compliance % (09-August-24) | N3: Compliance % (19-Aug-24) | O3: Compliance % (06-Sep-25) | P3: Compliance % (10-Oct-25)
B4: 1 | C4: Name A | D4: Service Reception | E4: 0.52694236 | F4: 0.32205514 | G4: 0.43671679 | H4: 0.68233083 | I4: 0.78007519 | J4: 0.75238095 | K4: 0.72738095 | L4: 0.75119048 | M4: 0.72738095 | N4: 0.76309524 | O4: 0.83809524 | P4: ='Service Reception'!S30 -> 0.70535714
B5: 2 | C5: Name A | D5: Interactive Reception | E5: 0.89473684 | F5: 0.73684211 | G5: 0.68421053 | H5: 0.94736842 | I5: 0.94736842 | J5: 0.94736842 | K5: 0.68421053 | L5: 0.57894737 | M5: 0.57894737 | N5: 0.94736842 | O5: 0.84210526 | P5: ='Service Reception'!S43 -> 0.84210526
B6: 3 | C6: Name A | D6: Customer Lounge | E6: 1 | F6: 1 | G6: 1 | H6: 1 | I6: 1 | J6: 0.85714286 | K6: 0.75 | L6: 0.85 | M6: 0.77272727 | N6: 0.94736842 | O6: 0.94736842 | P6: ='Service Reception'!S56 -> 1
B7: 4 | C7: Name A | D7: Aftersales Manager Room | E7: 1 | F7: 1 | G7: 1 | H7: 1 | I7: 1 | J7: 1 | K7: 1 | L7: 1 | M7: 1 | N7: 1 | O7: 1 | P7: ='Service Reception'!S69 -> 1
B8: 5 | C8: Name A | D8: Technical Manager Room | E8: - | F8: - | G8: - | H8: - | I8: - | J8: - | K8: - | L8: - | M8: - | N8: - | O8: - | P8: -
B9: 6 | C9: Name A | D9: Service Manager Room | E9: 1 | F9: 0.88235294 | G9: 0.88235294 | H9: 0.88235294 | I9: 0.88235294 | J9: 0.88235294 | K9: 0.88235294 | L9: 0.88235294 | M9: 0.88235294 | N9: 0.88235294 | O9: 0.88235294 | P9: ='Service Reception'!S82 -> 0
B10: 7 | C10: NA | D10: Office | E10: - | F10: - | G10: - | H10: - | I10: - | J10: - | K10: - | L10: - | M10: - | N10: - | O10: - | P10: -
B11: 8 | C11: Name B | D11: Workshop Zone A | E11: 0.47159091 | F11: 0.4744898 | G11: 0.57399103 | H11: 0.61502347 | I11: 0.73113208 | J11: 0.76303318 | K11: 0.6372093 | L11: 0.61538462 | M11: 0.56005932 | N11: 0.55411536 | O11: 0.59885208 | P11: ='Zone A'!K1 -> 0.68071736
B12: 9 | C12: Name C | D12: Workshop Zone B | E12: 0.65248227 | F12: 0.69387755 | G12: 0.58394161 | H12: 0.65925926 | I12: 0.82014388 | J12: 0.78472222 | K12: 0.64383562 | L12: 0.60273973 | M12: 0.58850323 | N12: 0.65753528 | O12: 0.63182621 | P12: ='Zone B'!K1 -> 0.73299233
B13: 10 | C13: NA | D13: Workshop Zone C (Car Washing area) | E13: 0.52941176 | F13: - | G13: - | H13: - | I13: - | J13: - | K13: - | L13: - | M13: - | N13: - | O13: - | P13: -
B14: 11 | C14: Name D | D14: Training Room | E14: 0.58333333 | F14: 0.58333333 | G14: 0.58333333 | H14: 0.83333333 | I14: 0.83333333 | J14: 0.6 | K14: 0.26666667 | L14: 0.30769231 | M14: 0.30769231 | N14: 0.30769231 | O14: 0.53846154 | P14: ='WSC Room'!L69 -> 0.53846154
B15: 12 | C15: Name D | D15: Power Room | E15: 0.8 | F15: 0.8 | G15: 1 | H15: 1 | I15: 1 | J15: 0.7 | K15: 0.7 | L15: 0.7 | M15: 1 | N15: 1 | O15: 1 | P15: -
B16: 13 | C16: Name D | D16: Archive Room | E16: 0.81818182 | F16: 0.81818182 | G16: 0.81818182 | H16: 1 | I16: 1 | J16: 1 | K16: 0.81818182 | L16: 0.81818182 | M16: 0.81818182 | N16: 0.81818182 | O16: 0.81818182 | P16: ='WSC Room'!L56 -> 0.81818182
B17: 14 | C17: Name D | D17: Parts Department | E17: 0.76190476 | F17: 0.80952381 | G17: 0.71428571 | H17: 0.72131148 | I17: 0.69354839 | J17: 0.66129032 | K17: 0.67741935 | L17: 0.70967742 | M17: 0.65671642 | N17: 0.68656716 | O17: 0.70967742 | P17: ='Parts, Warranty'!K1 -> 0.75438596
B18: 15 | C18: Name E | D18: Workshop Control Room | E18: 0.5625 | F18: 0.4375 | G18: 0.4375 | H18: 0.6875 | I18: 1 | J18: 0.88888889 | K18: 0.7 | L18: 0.77777778 | M18: 0.55555556 | N18: 0.625 | O18: 0.875 | P18: ='WSC Room'!L17 -> 0.82352941
B19: 16 | C19: Name E | D19: Unit Recondition Room | E19: 0.11764706 | F19: 0.41176471 | G19: 0.4375 | H19: 0.625 | I19: 0.625 | J19: 0.55555556 | K19: 0.52941176 | L19: 0.17647059 | M19: 0 | N19: 0.53333333 | O19: 0.17647059 | P19: ='WSC Room'!L30 -> 0.70588235
B20: 17 | C20: Name E | D20: Tool Room | E20: 1 | F20: 1 | G20: 1 | H20: 1 | I20: 1 | J20: 1 | K20: 1 | L20: 1 | M20: 1 | N20: 1 | O20: 1 | P20: ='WSC Room'!L43 -> 1
B21: 18 | C21: Name E | D21: Warranty Room | E21: 0.5 | F21: 0.5 | G21: 0.5 | H21: 0.75 | I21: 0.75 | J21: 0.65 | K21: 0.65 | L21: 0.75 | M21: 0.75 | N21: 0.75 | O21: 0.6 | P21: ='Parts, Warranty'!L70 -> 1
B22: 19 | C22: Name F | D22: Canteen | E22: 0.66666667 | F22: 0.66666667 | G22: 0.80952381 | H22: 0.80952381 | I22: 0.9047619 | J22: 0.9047619 | K22: 0.9047619 | L22: 0.9047619 | M22: 0.52380952 | N22: 0.52380952 | O22: 0.66666667 | P22: ='Canteen, Fm locker room'!L17 -> 0.66666667
B23: 20 | C23: Name F | D23: Female Locker Room | E23: 0.83333333 | F23: 0.83333333 | G23: 0.83333333 | H23: 0.83333333 | I23: 0.83333333 | J23: 0.83333333 | K23: 0.83333333 | L23: 0.83333333 | M23: 0.83333333 | N23: 0.83333333 | O23: 0.83333333 | P23: ='Canteen, Fm locker room'!L30 -> 0.83333333
B24: 21 | C24: Name F | D24: Female Rest Room | E24: - | F24: - | G24: - | H24: - | I24: - | J24: - | K24: - | L24: - | M24: - | N24: - | O24: - | P24: -
B25: 22 | C25: Name F | D25: Store Room | E25: - | F25: - | G25: - | H25: - | I25: - | J25: - | K25: - | L25: - | M25: - | N25: - | O25: - | P25: -
B26: 23 | C26: Name F | D26: Male Rest Room | E26: 0.9 | F26: 0.9 | G26: 0.9 | H26: 0.9 | I26: 0.9 | J26: 0.81818182 | K26: 0.9 | L26: 0.9 | M26: 0.9 | N26: 0.9 | O26: 0.9 | P26: ='Car washing, waste oil'!L43 -> 0.9
B27: 24 | C27: Name F | D27: Technician Locker Room | E27: 0.8 | F27: 0.8 | G27: 0.8 | H27: 0.8 | I27: 1 | J27: 0.72727273 | K27: 0.8 | L27: 0.8 | M27: 0.8 | N27: 0.8 | O27: 0.6 | P27: ='Car washing, waste oil'!L30 -> 0.8
B28: 25 | C28: Name F | D28: Waste Oil Storage | E28: 0.8 | F28: 0.8 | G28: 0.8 | H28: 0.8 | I28: 0.8 | J28: 0.8 | K28: 0.46666667 | L28: 0.46666667 | M28: 0.6 | N28: 0.6 | O28: 0.86666667 | P28: ='Car washing, waste oil'!L17 -> 1
B29: 26 | C29: Name F | D29: Outside | E29: - | F29: - | G29: - | H29: - | I29: - | J29: 0.58531746 | K29: 0.30634921 | L29: 0.4265873 | M29: 0.24801587 | N29: 0.48412698 | O29: 0.44708995 | P29: ='Car washing, waste oil'!L82 -> 0.62698413
B30: 27 | C30: NA | D30: Body shop | E30: - | F30: - | G30: - | H30: - | I30: - | J30: - | K30: - | L30: - | M30: - | N30: - | O30: - | P30: -
B31: 27 | C31: Service Manager | D31: Staff uniform | O31: 0.62 | P31: 0.62
D32: Overall 5S Compliance | E32: 0.72470148 | F32: 0.68904387 | G32: 0.73974355 | H32: 0.82731684 | I32: 0.87505247 | J32: 0.7957906 | K32: 0.70846572 | L32: 0.70722687 | M32: 0.67158457 | N32: 0.7435181 | O32: =AVERAGE(O4:O31) -> 0.74509764 | P32: =AVERAGE(P4:P31) -> 0.76421892
B34: N6A Branch ESMS Compliance Summary
B35: 1 | C35: ESMS | D35: Water Quality Compliance | E35: 0.36842105 | F35: 0.5 | G35: 0.5 | H35: 0.5 | I35: 0.5 | J35: 0.5 | K35: 0.5 | L35: 0.5 | M35: 0.5 | N35: 0.5 | O35: 0.5 | P35: ='ESMS-Water Quality'!K1 -> 0.5
B36: 2 | C36: ESMS | D36: Waste Segragation | E36: 0.63888889 | F36: 0.63888889 | G36: 0.61111111 | H36: 0.63888889 | I36: 0.63888889 | J36: 0.63888889 | K36: 0.63888889 | L36: 0.63888889 | M36: 0.63888889 | N36: 0.69444444 | O36: 0.69444444 | P36: ='ESMS-Waste segragation'!K1 -> 0.69444444

Sheet Summary for month
B2: 5S Compliance Summary
B3: Ch. No. | C3: Champion | D3: Allocated Area | E3: Compliance % (17-Oct-23) | F3: Compliance % (23-Oct-23) | G3: Compliance % (03-Nov-23) | H3: Compliance % (07-Nov-23) | I3: Compliance % (14-Nov-23) | J3: Compliance % (01-Dec-23) | K3: Compliance % (03-Jan-24) | L3: Compliance % (18-Jan-24) | M3: Compliance % (01-Feb-24) | N3: Compliance % (21-Feb-24) | O3: Compliance % (05-Mar-24) | P3: TSK | Q3: 6A | R3: QL | S3: MB | T3: PDI | U3: MV | V3: KPC | W3: SR
D4: Service Reception | E4: 0.58974359 | F4: 0.58974359 | G4: 0.58974359 | H4: ='[1]SA, Customer Lounge, IR'!$J$1 -> 0.84615385 | I4: 0.95 | J4: ='[2]SA, Customer Lounge, IR'!$J$1 -> 0.83783784 | K4: 0.54761905 | L4: =[3]SA!G5 -> 0.83333333 | M4: =[4]SA!G5 -> 0.875 | N4: 0.90983607 | O4: 0.90740741 | P4: =#REF! -> #REF! | Q4: =#REF! -> #REF! | R4: =#REF! -> #REF! | S4: =#REF! -> #REF! | T4: =#REF! -> #REF! | U4: =#REF! -> #REF! | V4: =#REF! -> #REF! | W4: =#REF! -> #REF!
D5: Customer Lounge | P5: =#REF! -> #REF! | Q5: =#REF! -> #REF! | R5: =#REF! -> #REF! | S5: =#REF! -> #REF! | T5: =#REF! -> #REF! | U5: =#REF! -> #REF! | V5: =#REF! -> #REF! | W5: =#REF! -> #REF!
D6: Interactive Reception | P6: =#REF! -> #REF! | Q6: =#REF! -> #REF! | R6: =#REF! -> #REF! | S6: =#REF! -> #REF! | T6: =#REF! -> #REF! | U6: =#REF! -> #REF! | V6: =#REF! -> #REF! | W6: =#REF! -> #REF!
D7: Aftersales Manager Room | P7: =#REF! -> #REF! | Q7: =#REF! -> #REF! | R7: =#REF! -> #REF! | S7: =#REF! -> #REF! | T7: NA | U7: =#REF! -> #REF! | V7: =#REF! -> #REF! | W7: =#REF! -> #REF!
D8: Service Manager Room | P8: =#REF! -> #REF! | Q8: =#REF! -> #REF! | R8: =#REF! -> #REF! | S8: =#REF! -> #REF! | T8: =#REF! -> #REF! | U8: =#REF! -> #REF! | V8: =#REF! -> #REF! | W8: =#REF! -> #REF!
D9: Office | P9: =#REF! -> #REF! | Q9: =#REF! -> #REF! | R9: =#REF! -> #REF! | S9: =#REF! -> #REF! | T9: =#REF! -> #REF! | U9: =#REF! -> #REF! | V9: =#REF! -> #REF! | W9: =#REF! -> #REF!
D10: Workshop Zone A | E10: 0.65060241 | F10: 0.81818182 | G10: 0.53846154 | H10: ='[1]Workshop (Zone A)'!J1 -> 0.81538462 | I10: 0.88 | J10: ='[2]Workshop (Zone A)'!J1 -> 0.76623377 | K10: 0.62745098 | L10: ='[3]Zone A '!G5 -> 0.78846154 | M10: ='[4]Zone A '!G5 -> 0.68316832 | N10: 0.77124183 | O10: 0.675 | P10: ='Zone A'!K1 -> 0.68071736 | Q10: ='Zone A'!L1 -> 0 | R10: ='Zone A'!M1 -> 0 | S10: ='Zone A'!N1 -> 0 | T10: ='Zone A'!O1 -> 0 | U10: ='Zone A'!P1 -> 0 | V10: NA | W10: ='Zone A'!R1 -> 0
D11: Workshop Zone B | E11: 0.49473684 | F11: 0.63855422 | G11: 0.34177215 | H11: ='[1]Workshop (Zone B)'!J1 -> 0.91780822 | I11: 1 | J11: ='[2]Workshop (Zone B)'!J1 -> 0.76 | K11: 0.59633028 | L11: ='[3]Zone B'!G5 -> 0.69090909 | M11: ='[4]Zone B'!G5 -> 0.68965517 | N11: 0.52873563 | O11: 0.49300699 | P11: ='Zone B'!K1 -> 0.73299233 | Q11: ='Zone B'!L1 -> 0 | R11: ='Zone B'!M1 -> 0 | S11: ='Zone B'!N1 -> 0 | T11: ='Zone B'!O1 -> 0 | U11: ='Zone B'!P1 -> 0 | V11: ='Zone B'!Q1 -> 0 | W11: ='Zone B'!R1 -> 0
D12: Workshop Zone C (Car Washing area) | E12: 0.24528302 | F12: 0.32075472 | G12: 0.40540541 | H12: ='[1]Washing area (Zone C)'!J1 -> 0.54929577 | I12: 0.97 | J12: ='[2]Washing area (Zone C)'!J1 -> 0.87341772 | K12: 0.33333333 | L12: ='[3]Car Washing'!$G$5 -> 0.7027027 | M12: ='[4]Car Washing'!$G$5 -> 0.7027027 | N12: 0.72 | O12: 0.66666667 | P12: ='Car washing'!K1 -> 0.62222222 | Q12: ='Car washing'!L1 -> 0 | R12: ='Car washing'!M1 -> 0 | S12: ='Car washing'!N1 -> 0 | T12: ='Car washing'!O1 -> 0 | U12: ='Car washing'!P1 -> 0 | V12: ='Car washing'!Q1 -> 0 | W12: ='Car washing'!R1 -> 0
D13: Training Room | P13: ='Unit recondition'!K6 -> 1 | Q13: ='Unit recondition'!L6 -> 0 | R13: ='Unit recondition'!M6 -> 0 | S13: ='Unit recondition'!N6 -> 0 | T13: ='Unit recondition'!O6 -> 0 | U13: ='Unit recondition'!P6 -> 0 | V13: ='Unit recondition'!Q6 -> 0 | W13: ='Unit recondition'!R6 -> 0
D14: Power Room | P14: ='Unit recondition'!K19 -> 0.46666667 | Q14: ='Unit recondition'!L19 -> 0 | R14: ='Unit recondition'!M19 -> 0 | S14: ='Unit recondition'!N19 -> 0 | T14: - | U14: ='Unit recondition'!P19 -> 0 | V14: ='Unit recondition'!Q19 -> 0 | W14: ='Unit recondition'!R19 -> 0
D15: Archive Room | P15: ='Unit recondition'!K45 -> 0.6 | Q15: ='Unit recondition'!L45 -> 0 | R15: ='Unit recondition'!M45 -> 0 | S15: ='Unit recondition'!N45 -> 0 | T15: ='Unit recondition'!O45 -> 0 | U15: ='Unit recondition'!P45 -> 0 | V15: ='Unit recondition'!Q45 -> 0 | W15: ='Unit recondition'!R45 -> 0
D16: Parts Department | E16: 0.68965517 | F16: 0.79310345 | G16: 0.79310345 | H16: ='[1] Parts Department'!J1 -> 0.86206897 | I16: 0.86 | J16: ='[2] Parts Department'!J1 -> 0.82758621 | K16: 0.45714286 | L16: ='[3]Part Dept'!G5 -> 0.71875 | M16: ='[4]Part Dept'!G5 -> 0.72 | N16: 0.84782609 | O16: 0.69387755 | P16: ='Parts, Warranty'!K1 -> 0.75438596 | Q16: ='Parts, Warranty'!L1 -> 0 | R16: ='Parts, Warranty'!M1 -> 0 | S16: ='Parts, Warranty'!N1 -> 0 | T16: ='Parts, Warranty'!O1 -> 0 | U16: NA | V16: ='Parts, Warranty'!Q1 -> 0 | W16: ='Parts, Warranty'!R1 -> 0
D17: Warehouse | P17: =#REF! -> #REF! | Q17: =#REF! -> #REF! | R17: =#REF! -> #REF! | S17: =#REF! -> #REF! | T17: =#REF! -> #REF! | U17: =#REF! -> #REF! | V17: =#REF! -> #REF! | W17: =#REF! -> #REF!
D18: Unit Recondition Room | P18: =#REF! -> #REF! | Q18: =#REF! -> #REF! | R18: =#REF! -> #REF! | S18: =#REF! -> #REF! | T18: =#REF! -> #REF! | U18: =#REF! -> #REF! | V18: =#REF! -> #REF! | W18: =#REF! -> #REF!
D19: Tool Room | E19: 0.2 | F19: 0.2 | G19: 0.66666667 | H19: ='[1]Tool room, Warranty room'!J1 -> 0.51612903 | I19: 0.77 | J19: ='[2]Tool room, Warranty room'!J1 -> 0.90322581 | K19: 0.5 | L19: ='[3]Tool Room'!G5 -> 0.625 | M19: ='[4]Tool Room'!G5 -> 0.55555556 | N19: 0.57142857 | O19: 0.58333333 | P19: ='WSC Room'!#REF! -> #REF! | Q19: ='WSC Room'!#REF! -> #REF! | R19: ='WSC Room'!#REF! -> #REF! | S19: ='WSC Room'!#REF! -> #REF! | T19: ='WSC Room'!#REF! -> #REF! | U19: ='WSC Room'!#REF! -> #REF! | V19: ='WSC Room'!#REF! -> #REF! | W19: ='WSC Room'!#REF! -> #REF!
D20: Warranty Room | P20: ='WSC Room'!#REF! -> #REF! | Q20: ='WSC Room'!#REF! -> #REF! | R20: ='WSC Room'!#REF! -> #REF! | S20: ='WSC Room'!#REF! -> #REF! | T20: ='WSC Room'!#REF! -> #REF! | U20: ='WSC Room'!#REF! -> #REF! | V20: ='WSC Room'!#REF! -> #REF! | W20: ='WSC Room'!#REF! -> #REF!
D21: Canteen | P21: =#REF! -> #REF! | Q21: =#REF! -> #REF! | R21: =#REF! -> #REF! | S21: =#REF! -> #REF! | T21: =#REF! -> #REF! | U21: =#REF! -> #REF! | V21: NA | W21: =#REF! -> #REF!
D22: Female Locker Room | P22: =#REF! -> #REF! | Q22: =#REF! -> #REF! | R22: =#REF! -> #REF! | S22: =#REF! -> #REF! | T22: =#REF! -> #REF! | U22: =#REF! -> #REF! | V22: =#REF! -> #REF! | W22: =#REF! -> #REF!
D23: Female Rest Room | P23: =#REF! -> #REF! | Q23: =#REF! -> #REF! | R23: =#REF! -> #REF! | S23: =#REF! -> #REF! | T23: =#REF! -> #REF! | U23: =#REF! -> #REF! | V23: =#REF! -> #REF! | W23: NA
D24: Male Rest Room | P24: =#REF! -> #REF! | Q24: =#REF! -> #REF! | R24: =#REF! -> #REF! | S24: =#REF! -> #REF! | T24: =#REF! -> #REF! | U24: =#REF! -> #REF! | V24: =#REF! -> #REF! | W24: =#REF! -> #REF!
D25: Technician Locker Room | P25: =#REF! -> #REF! | Q25: =#REF! -> #REF! | R25: =#REF! -> #REF! | S25: =#REF! -> #REF! | T25: =#REF! -> #REF! | U25: =#REF! -> #REF! | V25: =#REF! -> #REF! | W25: =#REF! -> #REF!
D26: Waste Oil Storage | P26: =#REF! -> #REF! | Q26: =#REF! -> #REF! | R26: =#REF! -> #REF! | S26: =#REF! -> #REF! | T26: =#REF! -> #REF! | U26: =#REF! -> #REF! | V26: =#REF! -> #REF! | W26: =#REF! -> #REF!
D27: Outside | E27: 0.16666667 | F27: 0.16666667 | G27: 0.41666667 | H27: ='[1]Rear room, Canteen, Outside'!J1 -> 0.41666667 | I27: 0.4 | J27: ='[2]Rear room, Canteen, Outside'!J1 -> 0.4 | K27: 0.48 | L27: ='[3]Rear Room'!G5 -> 0.57692308 | M27: ='[4]Rear Room'!G5 -> 0.7037037 | N27: 0.75555556 | O27: 0.69565217 | P27: =#REF! -> #REF! | Q27: =#REF! -> #REF! | R27: =#REF! -> #REF! | S27: =#REF! -> #REF! | T27: NA | U27: =#REF! -> #REF! | V27: =#REF! -> #REF! | W27: =#REF! -> #REF!
D28: Overall 5S Compliance | E28: 0.38260082 | F28: 0.46556676 | G28: 0.54258312 | H28: =SUM(H4:H27)/9 -> 0.54705635 | I28: 0.82 | J28: =SUM(J4:J27)/9 -> 0.59647793 | K28: 0.52422966 | L28: =SUM(L4:L27)/9 -> 0.5484533 | M28: =SUM(M4:M27)/9 -> 0.54775394 | N28: 0.72874835 | O28: 0.66109226 | P28: =SUM(P4:P27)/9 -> #REF! | Q28: =SUM(Q4:Q27)/9 -> #REF! | R28: =SUM(R4:R27)/9 -> #REF! | S28: =SUM(S4:S27)/9 -> #REF! | T28: =SUM(T4:T27)/9 -> #REF! | U28: =SUM(U4:U27)/9 -> #REF! | V28: =SUM(V4:V27)/9 -> #REF! | W28: =SUM(W4:W27)/9 -> #REF!
B30: Toul Sangke Branch ESMS Compliance Summary
B31: 1 | C31: ESMS | D31: Water Quality Compliance | E31: - | F31: - | G31: - | H31: - | I31: - | J31: ='[2]ESMS Water Quality'!J1 -> 0.1 | K31: 0.15 | L31: =[3]ESMS!$G$5 -> 0.2 | M31: =[4]ESMS!$G$5 -> 0.25 | N31: 0.44444444 | O31: 0.35714286 | P31: =#REF! -> #REF! | Q31: =#REF! -> #REF! | R31: =#REF! -> #REF! | S31: =#REF! -> #REF! | T31: =#REF! -> #REF! | U31: =#REF! -> #REF! | V31: =#REF! -> #REF! | W31: =#REF! -> #REF!
B32: 2 | C32: ESMS | D32: Waste Segragation | L32: - | M32: - | N32: 0.64583333 | O32: 0.64583333 | P32: =#REF! -> #REF! | Q32: =#REF! -> #REF! | R32: =#REF! -> #REF! | S32: =#REF! -> #REF! | T32: =#REF! -> #REF! | U32: =#REF! -> #REF! | V32: =#REF! -> #REF! | W32: =#REF! -> #REF!

Sheet Service Reception
A1: xx Branch 5S Checklist: SR, IR, Customer Lounge, ASM, SM | Q1: Compliance:
A3: SL | B3: Location | C3: Description | D3: Y/N | F3: NA | G3: Y | H3: N | I3: Comments | Q3: Picture | R3: Points
E5: =SUM(E6:E44) -> 53 | F5: =SUM(F6:F44) -> 4 | G5: =SUM(G6:G44) -> 92 | H5: =SUM(H6:H44) -> 27 | I5: =G5/(E5-F5) -> 1.877551
A6: 1 | B6: Service Reception | C6: Printer | D6: y | E6: 1 | F6: =IF($D6=$F$3,$E6,0) -> 0 | G6: =IF(D6=$G$3,$E6,0) -> 1 | H6: =IF($D6=$H$3,$E6,0) -> 0 | R6: =SUM(G6:G17)/SUM(G6:H17) -> 0.625
C7: Documents | D7: n | E7: 4 | F7: =IF(D7="NA",E7,0) -> 0 | G7: =IF(D7=$G$3,E7,0) -> 0 | H7: =IF($D7=$H$3,$E7,0) -> 4
C8: Chairs | D8: Y | E8: 1 | F8: =IF(D8="NA",E8,0) -> 0 | G8: =IF(D8=$G$3,E8,0) -> 1 | H8: =IF($D8=$H$3,$E8,0) -> 0
C9: Desk | D9: n | E9: 2 | F9: =IF(D9="NA",E9,0) -> 0 | G9: =IF(D9=$G$3,E9,0) -> 0 | H9: =IF($D9=$H$3,$E9,0) -> 2
C10: Floor cleanliness | D10: Y | E10: 3 | F10: =IF(D10="NA",E10,0) -> 0 | G10: =IF(D10=$G$3,E10,0) -> 3 | H10: =IF($D10=$H$3,$E10,0) -> 0
C11: Wall cleanliness | D11: y | E11: 2 | F11: =IF(D11="NA",E11,0) -> 0 | G11: =IF(D11=$G$3,E11,0) -> 2 | H11: =IF($D11=$H$3,$E11,0) -> 0 | I11: wall stain
C12: Roof cleanliness | D12: y | E12: 2 | F12: =IF(D12="NA",E12,0) -> 0 | G12: =IF(D12=$G$3,E12,0) -> 2 | H12: =IF($D12=$H$3,$E12,0) -> 0
C13: Bulb: Working | D13: Y | E13: 1 | F13: =IF(D13="NA",E13,0) -> 0 | G13: =IF(D13=$G$3,E13,0) -> 1 | H13: =IF($D13=$H$3,$E13,0) -> 0
C14: Other | D14: NA | E14: 4 | F14: =IF(D14="NA",E14,0) -> 4 | G14: =IF(D14=$G$3,E14,0) -> 0 | H14: =IF($D14=$H$3,$E14,0) -> 0
A19: 2 | B19: Service Reception | C19: Service Advisor Desk Check Poins | I19: 1 | J19: 2 | K19: 3 | L19: 4 | M19: 5 | N19: 6 | O19: 7 | P19: 8 | R19: =SUM(G19:G30)/SUM(G19:H30) -> 0.78571429
C20: Desk is well organised? | D20: Y | E20: 2 | F20: =IF(D20="NA",E20,0) -> 0 | G20: =COUNTIF(I20:P20,$G$3)*$E20 -> 8 | H20: =COUNTIF(I20:P20,$H$3)*$E20 -> 4 | I20: n | J20: y | K20: Y | L20: Y | M20: Y | N20: n
C21: Less than 7 items kept on the desk? | D21: Y | E21: 2 | F21: =IF(D21="NA",E21,0) -> 0 | G21: =COUNTIF(I21:P21,$G$3)*$E21 -> 8 | H21: =COUNTIF(I21:P21,$H$3)*$E21 -> 4 | I21: n | J21: Y | K21: Y | L21: Y | M21: Y | N21: n
C22: On desk is clean? | D22: Y | E22: 2 | F22: =IF(D22="NA",E22,0) -> 0 | G22: =COUNTIF(I22:P22,$G$3)*$E22 -> 6 | H22: =COUNTIF(I22:P22,$H$3)*$E22 -> 6 | I22: n | J22: n | K22: Y | L22: Y | M22: Y | N22: n
C23: Under the desk is clean? | D23: Y | E23: 2 | F23: =IF(D23="NA",E23,0) -> 0 | G23: =COUNTIF(I23:P23,$G$3)*$E23 -> 10 | H23: =COUNTIF(I23:P23,$H$3)*$E23 -> 2 | I23: Y | J23: Y | K23: Y | L23: Y | M23: Y | N23: n
C24: Less than 3 items kept under the desk? | D24: Y | E24: 2 | F24: =IF(D24="NA",E24,0) -> 0 | G24: =COUNTIF(I24:P24,$G$3)*$E24 -> 10 | H24: =COUNTIF(I24:P24,$H$3)*$E24 -> 2 | I24: Y | J24: Y | K24: Y | L24: Y | M24: Y | N24: n
C25: Monitor is not blocking SA face | D25: Y | E25: 2 | F25: =IF(D25="NA",E25,0) -> 0 | G25: =COUNTIF(I25:P25,$G$3)*$E25 -> 12 | H25: =COUNTIF(I25:P25,$H$3)*$E25 -> 0 | I25: Y | J25: Y | K25: Y | L25: Y | M25: Y | N25: Y
C26: Chair placement is correct? | D26: Y | E26: 2 | F26: =IF(D26="NA",E26,0) -> 0 | G26: =COUNTIF(I26:P26,$G$3)*$E26 -> 12 | H26: =COUNTIF(I26:P26,$H$3)*$E26 -> 0 | I26: Y | J26: Y | K26: Y | L26: Y | M26: Y | N26: Y
S30: =SUM(R6:R30)/2 -> 0.70535714
A32: 3 | B32: Interactive reception | C32: Fire Extingusher | D32: n | E32: 3 | F32: =IF($D32=$F$3,$E32,0) -> 0 | G32: =IF(D32=$G$3,$E32,0) -> 0 | H32: =IF($D32=$H$3,$E32,0) -> 3 | R32: =SUM(G32:G43)/SUM(G32:H43) -> 0.84210526
C33: Floor cleanliness | D33: Y | E33: 3 | F33: =IF(D33="NA",E33,0) -> 0 | G33: =IF(D33=$G$3,E33,0) -> 3 | H33: =IF($D33=$H$3,$E33,0) -> 0
C34: Lift cleanliness | D34: y | E34: 1 | F34: =IF(D34="NA",E34,0) -> 0 | G34: =IF(D34=$G$3,E34,0) -> 1 | H34: =IF($D34=$H$3,$E34,0) -> 0 | I34: Dusty under lift
C35: Free of Oil leaks/Spills/Trace | D35: Y | E35: 4 | F35: =IF(D35="NA",E35,0) -> 0 | G35: =IF(D35=$G$3,E35,0) -> 4 | H35: =IF($D35=$H$3,$E35,0) -> 0
C36: Wall cleanliness | D36: y | E36: 2 | F36: =IF(D36="NA",E36,0) -> 0 | G36: =IF(D36=$G$3,E36,0) -> 2 | H36: =IF($D36=$H$3,$E36,0) -> 0 | I36: Dust near to the wall
C37: Roof cleanliness | D37: Y | E37: 2 | F37: =IF(D37="NA",E37,0) -> 0 | G37: =IF(D37=$G$3,E37,0) -> 2 | H37: =IF($D37=$H$3,$E37,0) -> 0
C38: Glass cleanliness | D38: Y | E38: 2 | F38: =IF(D38="NA",E38,0) -> 0 | G38: =IF(D38=$G$3,E38,0) -> 2 | H38: =IF($D38=$H$3,$E38,0) -> 0
C39: TV | D39: Y | E39: 2 | F39: =IF(D39="NA",E39,0) -> 0 | G39: =IF(D39=$G$3,E39,0) -> 2 | H39: =IF($D39=$H$3,$E39,0) -> 0
S43: =R32 -> 0.84210526
A45: 4 | B45: Customer Lounge | C45: Bread Owen | D45: Y | E45: 1 | F45: =IF($D45=$F$3,$E45,0) -> 0 | G45: =IF(D45=$G$3,$E45,0) -> 1 | H45: =IF($D45=$H$3,$E45,0) -> 0 | R45: =SUM(G45:G56)/SUM(G45:H56) -> 1
C46: Refridgerator cleanliness | D46: Y | E46: 1 | F46: =IF(D46="NA",E46,0) -> 0 | G46: =IF(D46=$G$3,E46,0) -> 1 | H46: =IF($D46=$H$3,$E46,0) -> 0
C47: Café Machine | D47: Y | E47: 1 | F47: =IF(D47="NA",E47,0) -> 0 | G47: =IF(D47=$G$3,E47,0) -> 1 | H47: =IF($D47=$H$3,$E47,0) -> 0
C48: Chairs | D48: Y | E48: 1 | F48: =IF(D48="NA",E48,0) -> 0 | G48: =IF(D48=$G$3,E48,0) -> 1 | H48: =IF($D48=$H$3,$E48,0) -> 0
C49: Table | D49: Y | E49: 3 | F49: =IF(D49="NA",E49,0) -> 0 | G49: =IF(D49=$G$3,E49,0) -> 3 | H49: =IF($D49=$H$3,$E49,0) -> 0
C50: Dust Bin | D50: Y | E50: 1 | F50: =IF(D50="NA",E50,0) -> 0 | G50: =IF(D50=$G$3,E50,0) -> 1 | H50: =IF($D50=$H$3,$E50,0) -> 0
C51: Floor cleanliness | D51: Y | E51: 3 | F51: =IF(D51="NA",E51,0) -> 0 | G51: =IF(D51=$G$3,E51,0) -> 3 | H51: =IF($D51=$H$3,$E51,0) -> 0
C52: Wall cleanliness | D52: Y | E52: 2 | F52: =IF(D52="NA",E52,0) -> 0 | G52: =IF(D52=$G$3,E52,0) -> 2 | H52: =IF($D52=$H$3,$E52,0) -> 0
C53: Ceiling cleanliness | D53: Y | E53: 2 | F53: =IF(D53="NA",E53,0) -> 0 | G53: =IF(D53=$G$3,E53,0) -> 2 | H53: =IF($D53=$H$3,$E53,0) -> 0
C54: Exit sign | D54: Y | E54: 1 | F54: =IF(D54="NA",E54,0) -> 0 | G54: =IF(D54=$G$3,E54,0) -> 1 | H54: =IF($D54=$H$3,$E54,0) -> 0
...

Sheet Canteen, Fm locker room
A1: xx 5S Checklist: Canteen, Female locker room, Drive way | J1: Compliance:
A3: SL | B3: Location | C3: Description | D3: Y/N | F3: NA | G3: Y | H3: N | I3: Comments | J3: Picture | K3: Points
E5: =SUM(E6:E83) -> 49 | F5: =SUM(F6:F83) -> 0 | G5: =SUM(G6:G83) -> 37 | H5: =SUM(H6:H83) -> 12 | I5: =G5/(E5-F5) -> 0.75510204
A6: 1 | B6: Canteen | C6: Tables: Cleanliness | D6: Y | E6: 1 | F6: =IF($D6=$F$3,$E6,0) -> 0 | G6: =IF(D6=$G$3,$E6,0) -> 1 | H6: =IF($D6=$H$3,$E6,0) -> 0 | K6: =SUM(G6:G15)/SUM(G6:H15) -> 0.66666667
C7: Chairs: Cleanliness | D7: Y | E7: 1 | F7: =IF(D7="NA",E7,0) -> 0 | G7: =IF(D7=$G$3,E7,0) -> 1 | H7: =IF($D7=$H$3,$E7,0) -> 0
C8: Window Cleanliness | D8: N | E8: 2 | F8: =IF(D8="NA",E8,0) -> 0 | G8: =IF(D8=$G$3,E8,0) -> 0 | H8: =IF($D8=$H$3,$E8,0) -> 2 | I8: dusty
C9: Sink | D9: Y | E9: 2 | F9: =IF(D9="NA",E9,0) -> 0 | G9: =IF(D9=$G$3,E9,0) -> 2 | H9: =IF($D9=$H$3,$E9,0) -> 0
C10: Door cleanliness | D10: Y | E10: 2 | F10: =IF(D10="NA",E10,0) -> 0 | G10: =IF(D10=$G$3,E10,0) -> 2 | H10: =IF($D10=$H$3,$E10,0) -> 0
C11: Floor cleanliness | D11: n | E11: 3 | F11: =IF(D11="NA",E11,0) -> 0 | G11: =IF(D11=$G$3,E11,0) -> 0 | H11: =IF($D11=$H$3,$E11,0) -> 3
C12: Wall cleanliness | D12: n | E12: 2 | F12: =IF(D12="NA",E12,0) -> 0 | G12: =IF(D12=$G$3,E12,0) -> 0 | H12: =IF($D12=$H$3,$E12,0) -> 2
C13: Ceiling cleanliness | D13: Y | E13: 2 | F13: =IF(D13="NA",E13,0) -> 0 | G13: =IF(D13=$G$3,E13,0) -> 2 | H13: =IF($D13=$H$3,$E13,0) -> 0
C14: Break glass | D14: Y | E14: 3 | F14: =IF(D14="NA",E14,0) -> 0 | G14: =IF(D14=$G$3,E14,0) -> 3 | H14: =IF($D14=$H$3,$E14,0) -> 0
C15: Fire extinguisher:Cleanliness/Location | D15: Y | E15: 3 | F15: =IF(D15="NA",E15,0) -> 0 | G15: =IF(D15=$G$3,E15,0) -> 3 | H15: =IF($D15=$H$3,$E15,0) -> 0
L17: =K6 -> 0.66666667
A19: 2 | B19: Female locker room | C19: Chairs: Keep properly | D19: Y | E19: 1 | F19: =IF($D19=$F$3,$E19,0) -> 0 | G19: =IF(D19=$G$3,$E19,0) -> 1 | H19: =IF($D19=$H$3,$E19,0) -> 0 | K19: =SUM(G19:G28)/SUM(G19:H28) -> 0.83333333
C20: Door cleanliness | D20: Y | E20: 2 | F20: =IF(D20="NA",E20,0) -> 0 | G20: =IF(D20=$G$3,E20,0) -> 2 | H20: =IF($D20=$H$3,$E20,0) -> 0
C21: Floor cleanliness | D21: Y | E21: 3 | F21: =IF(D21="NA",E21,0) -> 0 | G21: =IF(D21=$G$3,E21,0) -> 3 | H21: =IF($D21=$H$3,$E21,0) -> 0
C22: Wall cleanliness | D22: N | E22: 2 | F22: =IF(D22="NA",E22,0) -> 0 | G22: =IF(D22=$G$3,E22,0) -> 0 | H22: =IF($D22=$H$3,$E22,0) -> 2 | I22: stain
C23: Ceiling cleanliness | D23: Y | E23: 2 | F23: =IF(D23="NA",E23,0) -> 0 | G23: =IF(D23=$G$3,E23,0) -> 2 | H23: =IF($D23=$H$3,$E23,0) -> 0
C24: Window: Cleanliness | D24: Y | E24: 2 | F24: =IF(D24="NA",E24,0) -> 0 | G24: =IF(D24=$G$3,E24,0) -> 2 | H24: =IF($D24=$H$3,$E24,0) -> 0
L30: =K19 -> 0.83333333
A32: 3 | B32: Outside | C32: Free from Trash | D32: n | E32: 1 | F32: =IF($D32=$F$3,$E32,0) -> 0 | G32: =IF(D32=$G$3,$E32,0) -> 0 | H32: =IF($D32=$H$3,$E32,0) -> 1 | K32: =SUM(G32:G41)/SUM(G32:H41) -> 0.7
C33: Wall cleanliness | D33: n | E33: 2 | F33: =IF(D33="NA",E33,0) -> 0 | G33: =IF(D33=$G$3,E33,0) -> 0 | H33: =IF($D33=$H$3,$E33,0) -> 2
C34: Pillar cleanliness | D34: Y | E34: 1 | F34: =IF(D34="NA",E34,0) -> 0 | G34: =IF(D34=$G$3,E34,0) -> 1 | H34: =IF($D34=$H$3,$E34,0) -> 0
C35: Drive way: Clear from car | D35: Y | E35: 2 | F35: =IF(D35="NA",E35,0) -> 0 | G35: =IF(D35=$G$3,E35,0) -> 2 | H35: =IF($D35=$H$3,$E35,0) -> 0
C36: Plants | D36: Y | E36: 2 | F36: =IF(D36="NA",E36,0) -> 0 | G36: =IF(D36=$G$3,E36,0) -> 2 | H36: =IF($D36=$H$3,$E36,0) -> 0
C37: Trash bin: Placement/Cleanliness | D37: Y | E37: 2 | F37: =IF(D37="NA",E37,0) -> 0 | G37: =IF(D37=$G$3,E37,0) -> 2 | H37: =IF($D37=$H$3,$E37,0) -> 0
A45: 4 | B45: Outside | C45: Free from Trash | D45: Y | E45: 1 | F45: =IF($D45=$F$3,$E45,0) -> 0 | G45: =IF(D45=$G$3,$E45,0) -> 1 | H45: =IF($D45=$H$3,$E45,0) -> 0 | K45: =SUM(G45:G54)/SUM(G45:H54) -> 1
C46: Wall cleanliness | D46: Y | E46: 2 | F46: =IF(D46="NA",E46,0) -> 0 | G46: =IF(D46=$G$3,E46,0) -> 2 | H46: =IF($D46=$H$3,$E46,0) -> 0
C47: Pillar cleanliness | D47: Y | E47: 1 | F47: =IF(D47="NA",E47,0) -> 0 | G47: =IF(D47=$G$3,E47,0) -> 1 | H47: =IF($D47=$H$3,$E47,0) -> 0
C48: Smoking area cleanliness | D48: Y | E48: 1 | F48: =IF(D48="NA",E48,0) -> 0 | G48: =IF(D48=$G$3,E48,0) -> 1 | H48: =IF($D48=$H$3,$E48,0) -> 0
C49: Plants | D49: Y | E49: 1 | F49: =IF(D49="NA",E49,0) -> 0 | G49: =IF(D49=$G$3,E49,0) -> 1 | H49: =IF($D49=$H$3,$E49,0) -> 0
L56: =SUM(K32:K56)/2 -> 0.85

Sheet Zone A
A1: xx Branch 5S Checklist: Workshop Zone A | J1: Compliance: | K1: =SUM(K7:K187)/14 -> 0.68071736
A3: SL | B3: Location | C3: Description | D3: Y/N | F3: NA | G3: Y | H3: N | I3: Comments | J3: Picture | K3: Points
E5: =SUM(E7:E187) -> 354 | F5: =SUM(F7:F187) -> 132 | G5: =SUM(G7:G187) -> 151 | H5: =SUM(H7:H187) -> 71 | I5: =G5/(E5-F5) -> 0.68018018
A7: 1 | B7: Wheel Alignment | C7: Dust bin: Placement | D7: NA | E7: 1 | F7: =IF($D7=$F$3,$E7,0) -> 1 | G7: =IF(D7=$G$3,$E7,0) -> 0 | H7: =IF($D7=$H$3,$E7,0) -> 0 | K7: =SUM(G7:G18)/SUM(G7:H18) -> 0.47368421
C8: Oil drainer: Cleanliness/Placement | D8: NA | E8: 1 | F8: =IF(D8="NA",E8,0) -> 1 | G8: =IF(D8=$G$3,E8,0) -> 0 | H8: =IF($D8=$H$3,$E8,0) -> 0
C9: Tool box: Cleanliness/Placement | D9: Y | E9: 2 | F9: =IF(D9="NA",E9,0) -> 0 | G9: =IF(D9=$G$3,E9,0) -> 2 | H9: =IF($D9=$H$3,$E9,0) -> 0
C10: Traffic pole | D10: NA | E10: 2 | F10: =IF(D10="NA",E10,0) -> 2 | G10: =IF(D10=$G$3,E10,0) -> 0 | H10: =IF($D10=$H$3,$E10,0) -> 0
C11: Fire Extingusher: Cleanliness/Location | D11: NA | E11: 3 | F11: =IF(D11="NA",E11,0) -> 3 | G11: =IF(D11=$G$3,E11,0) -> 0 | H11: =IF($D11=$H$3,$E11,0) -> 0
C12: Battery Charger | D12: NA | E12: 1 | F12: =IF(D12="NA",E12,0) -> 1 | G12: =IF(D12=$G$3,E12,0) -> 0 | H12: =IF($D12=$H$3,$E12,0) -> 0
C13: Floor cleanliness | D13: N | E13: 3 | F13: =IF(D13="NA",E13,0) -> 0 | G13: =IF(D13=$G$3,E13,0) -> 0 | H13: =IF($D13=$H$3,$E13,0) -> 3 | I13: Dust near wall/stain
C14: Lift cleanliness | D14: Y | E14: 1 | F14: =IF(D14="NA",E14,0) -> 0 | G14: =IF(D14=$G$3,E14,0) -> 1 | H14: =IF($D14=$H$3,$E14,0) -> 0
C15: Oil leaks/Spills | D15: Y | E15: 4 | F15: =IF(D15="NA",E15,0) -> 0 | G15: =IF(D15=$G$3,E15,0) -> 4 | H15: =IF($D15=$H$3,$E15,0) -> 0
C16: Wall cleanliness | D16: N | E16: 2 | F16: =IF(D16="NA",E16,0) -> 0 | G16: =IF(D16=$G$3,E16,0) -> 0 | H16: =IF($D16=$H$3,$E16,0) -> 2 | I16: paint off
C17: Roof cleanliness | D17: Y | E17: 2 | F17: =IF(D17="NA",E17,0) -> 0 | G17: =IF(D17=$G$3,E17,0) -> 2 | H17: =IF($D17=$H$3,$E17,0) -> 0
C18: Wheel allignment machine | D18: N | E18: 5 | F18: =IF(D18="NA",E18,0) -> 0 | G18: =IF(D18=$G$3,E18,0) -> 0 | H18: =IF($D18=$H$3,$E18,0) -> 5 | I18: Dust accumulated
A20: 2 | B20: Bay No 1 | C20: Dust bin: Placement | D20: NA | E20: 1 | F20: =IF($D20=$F$3,$E20,0) -> 1 | G20: =IF(D20=$G$3,$E20,0) -> 0 | H20: =IF($D20=$H$3,$E20,0) -> 0 | K20: =SUM(G20:G31)/SUM(G20:H31) -> 0.86666667
C21: Oil drainer: Cleanliness/Placement | D21: Y | E21: 1 | F21: =IF($D21=$F$3,$E21,0) -> 0 | G21: =IF(D21=$G$3,$E21,0) -> 1 | H21: =IF($D21=$H$3,$E21,0) -> 0
C22: Tool box: Cleanliness/Placement | D22: Y | E22: 2 | F22: =IF($D22=$F$3,$E22,0) -> 0 | G22: =IF(D22=$G$3,$E22,0) -> 2 | H22: =IF($D22=$H$3,$E22,0) -> 0
C23: Oil pump: Cleanliness/Placement | D23: NA | E23: 2 | F23: =IF($D23=$F$3,$E23,0) -> 2 | G23: =IF(D23=$G$3,$E23,0) -> 0 | H23: =IF($D23=$H$3,$E23,0) -> 0
C24: Fire Extingusher: Cleanliness/Location | D24: NA | E24: 3 | F24: =IF($D24=$F$3,$E24,0) -> 3 | G24: =IF(D24=$G$3,$E24,0) -> 0 | H24: =IF($D24=$H$3,$E24,0) -> 0
C25: Cleaning Kit: | D25: NA | E25: 3 | F25: =IF($D25=$F$3,$E25,0) -> 3 | G25: =IF(D25=$G$3,$E25,0) -> 0 | H25: =IF($D25=$H$3,$E25,0) -> 0
C26: Floor cleanliness | D26: Y | E26: 3 | F26: =IF($D26=$F$3,$E26,0) -> 0 | G26: =IF(D26=$G$3,$E26,0) -> 3 | H26: =IF($D26=$H$3,$E26,0) -> 0
C27: Lift cleanliness | D27: Y | E27: 1 | F27: =IF($D27=$F$3,$E27,0) -> 0 | G27: =IF(D27=$G$3,$E27,0) -> 1 | H27: =IF($D27=$H$3,$E27,0) -> 0
C28: Free Oil leaks/Spills | D28: Y | E28: 4 | F28: =IF($D28=$F$3,$E28,0) -> 0 | G28: =IF(D28=$G$3,$E28,0) -> 4 | H28: =IF($D28=$H$3,$E28,0) -> 0
C29: Wall cleanliness | D29: N | E29: 2 | F29: =IF($D29=$F$3,$E29,0) -> 0 | G29: =IF(D29=$G$3,$E29,0) -> 0 | H29: =IF($D29=$H$3,$E29,0) -> 2 | I29: Stain, paint off
C30: Roof cleanliness | D30: Y | E30: 2 | F30: =IF($D30=$F$3,$E30,0) -> 0 | G30: =IF(D30=$G$3,$E30,0) -> 2 | H30: =IF($D30=$H$3,$E30,0) -> 0
C31: Other | D31: NA | E31: 2 | F31: =IF($D31=$F$3,$E31,0) -> 2 | G31: =IF(D31=$G$3,$E31,0) -> 0 | H31: =IF($D31=$H$3,$E31,0) -> 0
A33: 3 | B33: Bay No 2 | C33: Dust bin: Placement | D33: Y | E33: 1 | F33: =IF($D33=$F$3,$E33,0) -> 0 | G33: =IF(D33=$G$3,$E33,0) -> 1 | H33: =IF($D33=$H$3,$E33,0) -> 0 | K33: =SUM(G33:G44)/SUM(G33:H44) -> 0.61111111
C34: Oil drainer: Cleanliness/Placement | D34: NA | E34: 1 | F34: =IF(D34="NA",E34,0) -> 1 | G34: =IF(D34=$G$3,E34,0) -> 0 | H34: =IF($D34=$H$3,$E34,0) -> 0
C35: Tool box: Cleanliness/Placement | D35: Y | E35: 2 | F35: =IF(D35="NA",E35,0) -> 0 | G35: =IF(D35=$G$3,E35,0) -> 2 | H35: =IF($D35=$H$3,$E35,0) -> 0
C36: Oil pump: Cleanliness/Placement | D36: Y | E36: 2 | F36: =IF(D36="NA",E36,0) -> 0 | G36: =IF(D36=$G$3,E36,0) -> 2 | H36: =IF($D36=$H$3,$E36,0) -> 0
C37: Fire Extingusher: Cleanliness/Location | D37: NA | E37: 3 | F37: =IF(D37="NA",E37,0) -> 3 | G37: =IF(D37=$G$3,E37,0) -> 0 | H37: =IF($D37=$H$3,$E37,0) -> 0
C38: Cleaning Kit: | D38: NA | E38: 3 | F38: =IF(D38="NA",E38,0) -> 3 | G38: =IF(D38=$G$3,E38,0) -> 0 | H38: =IF($D38=$H$3,$E38,0) -> 0
C39: Floor cleanliness | D39: N | E39: 3 | F39: =IF(D39="NA",E39,0) -> 0 | G39: =IF(D39=$G$3,E39,0) -> 0 | H39: =IF($D39=$H$3,$E39,0) -> 3 | I39: Dust near to the wall/ stain
C40: Lift cleanliness | D40: N | E40: 1 | F40: =IF(D40="NA",E40,0) -> 0 | G40: =IF(D40=$G$3,E40,0) -> 0 | H40: =IF($D40=$H$3,$E40,0) -> 1 | I40: Dust accumulated near the lift
C41: Free oil leaks/Spills | D41: Y | E41: 4 | F41: =IF(D41="NA",E41,0) -> 0 | G41: =IF(D41=$G$3,E41,0) -> 4 | H41: =IF($D41=$H$3,$E41,0) -> 0
C42: Wall cleanliness | D42: N | E42: 2 | F42: =IF(D42="NA",E42,0) -> 0 | G42: =IF(D42=$G$3,E42,0) -> 0 | H42: =IF($D42=$H$3,$E42,0) -> 2 | I42: Stain/paint off
C43: Roof cleanliness | D43: Y | E43: 2 | F43: =IF(D43="NA",E43,0) -> 0 | G43: =IF(D43=$G$3,E43,0) -> 2 | H43: =IF($D43=$H$3,$E43,0) -> 0
C44: Others | D44: N | E44: 1 | F44: =IF(D44="NA",E44,0) -> 0 | G44: =IF(D44=$G$3,E44,0) -> 0 | H44: =IF($D44=$H$3,$E44,0) -> 1 | I44: Oil can not kept in designated location
A46: 4 | B46: Bay No 3 | C46: Dust bin: Placement | D46: NA | E46: 1 | F46: =IF($D46=$F$3,$E46,0) -> 1 | G46: =IF(D46=$G$3,$E46,0) -> 0 | H46: =IF($D46=$H$3,$E46,0) -> 0 | K46: =SUM(G46:G57)/SUM(G46:H57) -> 0.78571429
...

Sheet Zone B
A1: xx Branch 5S Checklist: Workshop Zone B | J1: Compliance: | K1: =SUM(K7:K187)/9 -> 0.73299233
A3: SL | B3: Location | C3: Description | D3: Y/N | F3: NA | G3: Y | H3: N | I3: Comments | J3: Picture | K3: Points
E5: =SUM(E7:E123) -> 211 | F5: =SUM(F7:F123) -> 65 | G5: =SUM(G7:G123) -> 106 | H5: =SUM(H7:H123) -> 40 | I5: =G5/(E5-F5) -> 0.7260274
A7: 1 | B7: Work Planner Board | C7: Job Card Placement/Cleanliness | D7: Y | E7: 1 | F7: =IF($D7=$F$3,$E7,0) -> 0 | G7: =IF(D7=$G$3,$E7,0) -> 1 | H7: =IF($D7=$H$3,$E7,0) -> 0 | K7: =SUM(G7:G18)/SUM(G7:H18) -> 0.85714286
C8: Clocking Machine | D8: Y | E8: 1 | F8: =IF(D8="NA",E8,0) -> 0 | G8: =IF(D8=$G$3,E8,0) -> 1 | H8: =IF($D8=$H$3,$E8,0) -> 0
C9: Monitor | D9: N | E9: 2 | F9: =IF(D9="NA",E9,0) -> 0 | G9: =IF(D9=$G$3,E9,0) -> 0 | H9: =IF($D9=$H$3,$E9,0) -> 2 | I9: dusty at the back of keyboard
C10: Table | D10: NA | E10: 2 | F10: =IF(D10="NA",E10,0) -> 2 | G10: =IF(D10=$G$3,E10,0) -> 0 | H10: =IF($D10=$H$3,$E10,0) -> 0
C11: Chairs | D11: Y | E11: 3 | F11: =IF(D11="NA",E11,0) -> 0 | G11: =IF(D11=$G$3,E11,0) -> 3 | H11: =IF($D11=$H$3,$E11,0) -> 0
C12: Cleaning Kit: | D12: NA | E12: 3 | F12: =IF(D12="NA",E12,0) -> 3 | G12: =IF(D12=$G$3,E12,0) -> 0 | H12: =IF($D12=$H$3,$E12,0) -> 0
C13: Floor cleanliness | D13: Y | E13: 3 | F13: =IF(D13="NA",E13,0) -> 0 | G13: =IF(D13=$G$3,E13,0) -> 3 | H13: =IF($D13=$H$3,$E13,0) -> 0
C14: Wall cleanliness | D14: Y | E14: 2 | F14: =IF(D14="NA",E14,0) -> 0 | G14: =IF(D14=$G$3,E14,0) -> 2 | H14: =IF($D14=$H$3,$E14,0) -> 0
C15: Roof cleanliness | D15: Y | E15: 2 | F15: =IF(D15="NA",E15,0) -> 0 | G15: =IF(D15=$G$3,E15,0) -> 2 | H15: =IF($D15=$H$3,$E15,0) -> 0
C16: Others | D16: NA | E16: 2 | F16: =IF(D16="NA",E16,0) -> 2 | G16: =IF(D16=$G$3,E16,0) -> 0 | H16: =IF($D16=$H$3,$E16,0) -> 0
A20: 2 | B20: Bay No 14 | C20: Dust bin: Placement | D20: NA | E20: 1 | F20: =IF($D20=$F$3,$E20,0) -> 1 | G20: =IF(D20=$G$3,$E20,0) -> 0 | H20: =IF($D20=$H$3,$E20,0) -> 0 | K20: =SUM(G20:G31)/SUM(G20:H31) -> 0.86666667
C21: Oil drainer: Cleanliness/Placement | D21: Y | E21: 1 | F21: =IF(D21="NA",E21,0) -> 0 | G21: =IF(D21=$G$3,E21,0) -> 1 | H21: =IF($D21=$H$3,$E21,0) -> 0
C22: Tool box: Cleanliness/Placement | D22: Y | E22: 2 | F22: =IF(D22="NA",E22,0) -> 0 | G22: =IF(D22=$G$3,E22,0) -> 2 | H22: =IF($D22=$H$3,$E22,0) -> 0
C23: Oil pump: Cleanliness/Placement | D23: NA | E23: 2 | F23: =IF(D23="NA",E23,0) -> 2 | G23: =IF(D23=$G$3,E23,0) -> 0 | H23: =IF($D23=$H$3,$E23,0) -> 0
C24: Fire Extingusher: Cleanliness/Location | D24: NA | E24: 3 | F24: =IF(D24="NA",E24,0) -> 3 | G24: =IF(D24=$G$3,E24,0) -> 0 | H24: =IF($D24=$H$3,$E24,0) -> 0
C25: Cleaning Kit: | D25: NA | E25: 3 | F25: =IF(D25="NA",E25,0) -> 3 | G25: =IF(D25=$G$3,E25,0) -> 0 | H25: =IF($D25=$H$3,$E25,0) -> 0
C26: Floor cleanliness | D26: Y | E26: 3 | F26: =IF(D26="NA",E26,0) -> 0 | G26: =IF(D26=$G$3,E26,0) -> 3 | H26: =IF($D26=$H$3,$E26,0) -> 0
C27: Lift cleanliness | D27: Y | E27: 1 | F27: =IF(D27="NA",E27,0) -> 0 | G27: =IF(D27=$G$3,E27,0) -> 1 | H27: =IF($D27=$H$3,$E27,0) -> 0
C28: Free Oil leaks/Spills | D28: Y | E28: 4 | F28: =IF(D28="NA",E28,0) -> 0 | G28: =IF(D28=$G$3,E28,0) -> 4 | H28: =IF($D28=$H$3,$E28,0) -> 0
C29: Wall cleanliness | D29: N | E29: 2 | F29: =IF(D29="NA",E29,0) -> 0 | G29: =IF(D29=$G$3,E29,0) -> 0 | H29: =IF($D29=$H$3,$E29,0) -> 2 | I29: Stain, paint off
C30: Roof cleanliness | D30: Y | E30: 2 | F30: =IF(D30="NA",E30,0) -> 0 | G30: =IF(D30=$G$3,E30,0) -> 2 | H30: =IF($D30=$H$3,$E30,0) -> 0
C31: Others
A33: 3 | B33: Bay No 15 | C33: Dust bin: Placement | D33: Y | E33: 1 | F33: =IF($D33=$F$3,$E33,0) -> 0 | G33: =IF(D33=$G$3,$E33,0) -> 1 | H33: =IF($D33=$H$3,$E33,0) -> 0 | K33: =SUM(G33:G44)/SUM(G33:H44) -> 0.88235294
C34: Oil drainer: Cleanliness/Placement | D34: NA | E34: 1 | F34: =IF(D34="NA",E34,0) -> 1 | G34: =IF(D34=$G$3,E34,0) -> 0 | H34: =IF($D34=$H$3,$E34,0) -> 0
C35: Tool box: Cleanliness/Placement | D35: Y | E35: 2 | F35: =IF(D35="NA",E35,0) -> 0 | G35: =IF(D35=$G$3,E35,0) -> 2 | H35: =IF($D35=$H$3,$E35,0) -> 0
C36: Oil pump: Cleanliness/Placement | D36: Y | E36: 2 | F36: =IF(D36="NA",E36,0) -> 0 | G36: =IF(D36=$G$3,E36,0) -> 2 | H36: =IF($D36=$H$3,$E36,0) -> 0
C37: Fire Extingusher: Cleanliness/Location | D37: NA | E37: 3 | F37: =IF(D37="NA",E37,0) -> 3 | G37: =IF(D37=$G$3,E37,0) -> 0 | H37: =IF($D37=$H$3,$E37,0) -> 0
C38: Cleaning Kit: | D38: NA | E38: 3 | F38: =IF(D38="NA",E38,0) -> 3 | G38: =IF(D38=$G$3,E38,0) -> 0 | H38: =IF($D38=$H$3,$E38,0) -> 0
C39: Floor cleanliness | D39: Y | E39: 3 | F39: =IF(D39="NA",E39,0) -> 0 | G39: =IF(D39=$G$3,E39,0) -> 3 | H39: =IF($D39=$H$3,$E39,0) -> 0
C40: Lift cleanliness | D40: Y | E40: 1 | F40: =IF(D40="NA",E40,0) -> 0 | G40: =IF(D40=$G$3,E40,0) -> 1 | H40: =IF($D40=$H$3,$E40,0) -> 0
C41: Free Oil leaks/Spills | D41: Y | E41: 4 | F41: =IF(D41="NA",E41,0) -> 0 | G41: =IF(D41=$G$3,E41,0) -> 4 | H41: =IF($D41=$H$3,$E41,0) -> 0
C42: Wall cleanliness | D42: N | E42: 2 | F42: =IF(D42="NA",E42,0) -> 0 | G42: =IF(D42=$G$3,E42,0) -> 0 | H42: =IF($D42=$H$3,$E42,0) -> 2 | I42: Stain/paint off
C43: Roof cleanliness | D43: Y | E43: 2 | F43: =IF(D43="NA",E43,0) -> 0 | G43: =IF(D43=$G$3,E43,0) -> 2 | H43: =IF($D43=$H$3,$E43,0) -> 0
C44: Others
A46: 4 | B46: Bay No 16 | C46: Dust bin: Placement | D46: Y | E46: 1 | F46: =IF($D46=$F$3,$E46,0) -> 0 | G46: =IF(D46=$G$3,$E46,0) -> 1 | H46: =IF($D46=$H$3,$E46,0) -> 0 | K46: =SUM(G46:G57)/SUM(G46:H57) -> 0.66666667
C47: Oil drainer: Cleanliness/Placement | D47: NA | E47: 1 | F47: =IF(D47="NA",E47,0) -> 1 | G47: =IF(D47=$G$3,E47,0) -> 0 | H47: =IF($D47=$H$3,$E47,0) -> 0
C48: Tool box: Cleanliness/Placement | D48: Y | E48: 2 | F48: =IF(D48="NA",E48,0) -> 0 | G48: =IF(D48=$G$3,E48,0) -> 2 | H48: =IF($D48=$H$3,$E48,0) -> 0
...

Sheet Car washing
A1: Toul Sangke 5S Checklist: Car Washing Area | J1: Compliance: | K1: =I5 -> 0.62222222
A3: SL | B3: Location | C3: Description | D3: Y/N | F3: NA | G3: Y | H3: N | I3: Comments | J3: Picture | K3: Points
E5: =SUM(E6:E122) -> 52 | F5: =SUM(F6:F122) -> 7 | G5: =SUM(G6:G122) -> 28 | H5: =SUM(H6:H122) -> 17 | I5: =G5/(E5-F5) -> 0.62222222
A6: 1 | B6: Car washing | C6: Vacum Cleaner : Placement | D6: Y | E6: 1 | F6: =IF($D6=$F$3,$E6,0) -> 0 | G6: =IF(D6=$G$3,$E6,0) -> 1 | H6: =IF($D6=$H$3,$E6,0) -> 0 | K6: =COUNTIF(D6:D17,"Y") -> 6
C7: Cabinet | D7: Y | E7: 1 | F7: =IF(D7="NA",E7,0) -> 0 | G7: =IF(D7=$G$3,E7,0) -> 1 | H7: =IF($D7=$H$3,$E7,0) -> 0
C8: Rack | D8: Y | E8: 2 | F8: =IF(D8="NA",E8,0) -> 0 | G8: =IF(D8=$G$3,E8,0) -> 2 | H8: =IF($D8=$H$3,$E8,0) -> 0
C9: Floor cleanliness | D9: N | E9: 3 | F9: =IF(D9="NA",E9,0) -> 0 | G9: =IF(D9=$G$3,E9,0) -> 0 | H9: =IF($D9=$H$3,$E9,0) -> 3 | I9: Dusty near water tank
C10: Wall cleanliness | D10: Y | E10: 2 | F10: =IF(D10="NA",E10,0) -> 0 | G10: =IF(D10=$G$3,E10,0) -> 2 | H10: =IF($D10=$H$3,$E10,0) -> 0
C11: Roof cleanliness | D11: Y | E11: 2 | F11: =IF(D11="NA",E11,0) -> 0 | G11: =IF(D11=$G$3,E11,0) -> 2 | H11: =IF($D11=$H$3,$E11,0) -> 0
C12: Chairs | D12: Y | E12: 1 | F12: =IF(D12="NA",E12,0) -> 0 | G12: =IF(D12=$G$3,E12,0) -> 1 | H12: =IF($D12=$H$3,$E12,0) -> 0
C13: Others
A19: 2 | B19: Car washing | C19: Car washing machine: Placement/Cleanliness | D19: Y | E19: 1 | F19: =IF($D19=$F$3,$E19,0) -> 0 | G19: =IF(D19=$G$3,$E19,0) -> 1 | H19: =IF($D19=$H$3,$E19,0) -> 0 | K19: =COUNTIF(D19:D30,"Y") -> 3
C20: Bucket: Placement | D20: Y | E20: 1 | F20: =IF(D20="NA",E20,0) -> 0 | G20: =IF(D20=$G$3,E20,0) -> 1 | H20: =IF($D20=$H$3,$E20,0) -> 0
C21: Warranty tires: Placement | D21: Y | E21: 2 | F21: =IF(D21="NA",E21,0) -> 0 | G21: =IF(D21=$G$3,E21,0) -> 2 | H21: =IF($D21=$H$3,$E21,0) -> 0
A32: 3 | B32: PDI bay | C32: Dust Bin | D32: N | E32: 1 | F32: =IF($D32=$F$3,$E32,0) -> 0 | G32: =IF(D32=$G$3,$E32,0) -> 0 | H32: =IF($D32=$H$3,$E32,0) -> 1 | I32: Dusty | K32: =COUNTIF(D32:D39,"Y") -> 2
C33: Tool box: Cleanliness/Placement | D33: N | E33: 1 | F33: =IF(D33="NA",E33,0) -> 0 | G33: =IF(D33=$G$3,E33,0) -> 0 | H33: =IF($D33=$H$3,$E33,0) -> 1 | I33: Not in designated location
C34: Fire Extingusher: Cleanliness/Location | D34: Y | E34: 3 | F34: =IF(D34="NA",E34,0) -> 0 | G34: =IF(D34=$G$3,E34,0) -> 3 | H34: =IF($D34=$H$3,$E34,0) -> 0
C35: Cleaning Kit: | D35: NA | E35: 1 | F35: =IF(D35="NA",E35,0) -> 1 | G35: =IF(D35=$G$3,E35,0) -> 0 | H35: =IF($D35=$H$3,$E35,0) -> 0
C36: Floor cleanliness | D36: N | E36: 3 | F36: =IF(D36="NA",E36,0) -> 0 | G36: =IF(D36=$G$3,E36,0) -> 0 | H36: =IF($D36=$H$3,$E36,0) -> 3 | I36: Dusty
C37: Lift cleanliness | D37: N | E37: 1 | F37: =IF(D37="NA",E37,0) -> 0 | G37: =IF(D37=$G$3,E37,0) -> 0 | H37: =IF($D37=$H$3,$E37,0) -> 1 | I37: Rust,Dust
C38: Free of Oil leaks/Spills/Trace | D38: N | E38: 4 | F38: =IF(D38="NA",E38,0) -> 0 | G38: =IF(D38=$G$3,E38,0) -> 0 | H38: =IF($D38=$H$3,$E38,0) -> 4 | I38: Oil leak
C39: Wall cleanliness | D39: Y | E39: 2 | F39: =IF(D39="NA",E39,0) -> 0 | G39: =IF(D39=$G$3,E39,0) -> 2 | H39: =IF($D39=$H$3,$E39,0) -> 0
C40: Roof cleanliness | D40: Y | E40: 2 | F40: =IF(D40="NA",E40,0) -> 0 | G40: =IF(D40=$G$3,E40,0) -> 2 | H40: =IF($D40=$H$3,$E40,0) -> 0
C41: Other | D41: N | I41: Oil drainer not in designated location
A45: 4 | B45: PDI bay | C45: Dust Bin | D45: NA | E45: 1 | F45: =IF($D45=$F$3,$E45,0) -> 1 | G45: =IF(D45=$G$3,$E45,0) -> 0 | H45: =IF($D45=$H$3,$E45,0) -> 0 | K45: =COUNTIF(D45:D56,"Y") -> 3
C46: Tool box: Cleanliness/Placement | D46: NA | E46: 1 | F46: =IF($D46=$F$3,$E46,0) -> 1 | G46: =IF(D46=$G$3,$E46,0) -> 0 | H46: =IF($D46=$H$3,$E46,0) -> 0
C47: Fire Extingusher: Cleanliness/Location | D47: NA | E47: 3 | F47: =IF($D47=$F$3,$E47,0) -> 3 | G47: =IF(D47=$G$3,$E47,0) -> 0 | H47: =IF($D47=$H$3,$E47,0) -> 0
C48: Cleaning Kit: | D48: NA | E48: 1 | F48: =IF($D48=$F$3,$E48,0) -> 1 | G48: =IF(D48=$G$3,$E48,0) -> 0 | H48: =IF($D48=$H$3,$E48,0) -> 0
C49: Floor cleanliness | D49: N | E49: 3 | F49: =IF($D49=$F$3,$E49,0) -> 0 | G49: =IF(D49=$G$3,$E49,0) -> 0 | H49: =IF($D49=$H$3,$E49,0) -> 3 | I49: Dusty
C50: Lift cleanliness | D50: N | E50: 1 | F50: =IF($D50=$F$3,$E50,0) -> 0 | G50: =IF(D50=$G$3,$E50,0) -> 0 | H50: =IF($D50=$H$3,$E50,0) -> 1 | I50: Rust,Dust
C51: Free of Oil leaks/Spills/Trace | D51: Y | E51: 4 | F51: =IF($D51=$F$3,$E51,0) -> 0 | G51: =IF(D51=$G$3,$E51,0) -> 4 | H51: =IF($D51=$H$3,$E51,0) -> 0
C52: Wall cleanliness | D52: Y | E52: 2 | F52: =IF($D52=$F$3,$E52,0) -> 0 | G52: =IF(D52=$G$3,$E52,0) -> 2 | H52: =IF($D52=$H$3,$E52,0) -> 0
C53: Roof cleanliness | D53: Y | E53: 2 | F53: =IF($D53=$F$3,$E53,0) -> 0 | G53: =IF(D53=$G$3,$E53,0) -> 2 | H53: =IF($D53=$H$3,$E53,0) -> 0

Sheet Unit recondition
A1: Toul Sangke 5S Checklist:Training Room, Power Room, Archive Room | J1: Compliance:
A3: SL | B3: Location | C3: Description | D3: Y/N | F3: NA | G3: Y | H3: N | I3: Comments | J3: Picture | K3: Points
E5: =SUM(E6:E122) -> 59 | F5: =SUM(F6:F122) -> 0 | G5: =SUM(G6:G122) -> 37 | H5: =SUM(H6:H122) -> 22 | I5: =G5/(E5-F5) -> 0.62711864
A6: 2 | B6: Training room | C6: Table: Placement/Cleanliness | D6: Y | E6: 1 | F6: =IF($D6=$F$3,$E6,0) -> 0 | G6: =IF(D6=$G$3,$E6,0) -> 1 | H6: =IF($D6=$H$3,$E6,0) -> 0 | K6: =SUM(G6:G17)/SUM(G6:H17) -> 1
C7: Chairs: Placement/Cleanliness | D7: Y | E7: 1 | F7: =IF(D7="NA",E7,0) -> 0 | G7: =IF(D7=$G$3,E7,0) -> 1 | H7: =IF($D7=$H$3,$E7,0) -> 0
C8: Board: Placement/Cleanliness | D8: Y | E8: 1 | F8: =IF(D8="NA",E8,0) -> 0 | G8: =IF(D8=$G$3,E8,0) -> 1 | H8: =IF($D8=$H$3,$E8,0) -> 0
C9: Cabinet: Placement/Cleanliness | D9: Y | E9: 1 | F9: =IF(D9="NA",E9,0) -> 0 | G9: =IF(D9=$G$3,E9,0) -> 1 | H9: =IF($D9=$H$3,$E9,0) -> 0
C10: Engine: Placement/Cleanliness | D10: Y | E10: 1 | F10: =IF(D10="NA",E10,0) -> 0 | G10: =IF(D10=$G$3,E10,0) -> 1 | H10: =IF($D10=$H$3,$E10,0) -> 0
C11: Floor cleanliness | D11: Y | E11: 3 | F11: =IF(D11="NA",E11,0) -> 0 | G11: =IF(D11=$G$3,E11,0) -> 3 | H11: =IF($D11=$H$3,$E11,0) -> 0
C12: Free of Oil leaks/Spills | D12: Y | E12: 4 | F12: =IF($D12=$F$3,$E12,0) -> 0 | G12: =IF(D12=$G$3,$E12,0) -> 4 | H12: =IF($D12=$H$3,$E12,0) -> 0
C13: Wall cleanliness | D13: Y | E13: 2 | F13: =IF(D13="NA",E13,0) -> 0 | G13: =IF(D13=$G$3,E13,0) -> 2 | H13: =IF($D13=$H$3,$E13,0) -> 0
C14: Roof cleanliness | D14: Y | E14: 2 | F14: =IF(D14="NA",E14,0) -> 0 | G14: =IF(D14=$G$3,E14,0) -> 2 | H14: =IF($D14=$H$3,$E14,0) -> 0
C15: Work bench: Cleanliness | D15: Y | E15: 1 | F15: =IF(D15="NA",E15,0) -> 0 | G15: =IF(D15=$G$3,E15,0) -> 1 | H15: =IF($D15=$H$3,$E15,0) -> 0
C16: Drinking water | D16: Y | E16: 1 | F16: =IF(D16="NA",E16,0) -> 0 | G16: =IF(D16=$G$3,E16,0) -> 1 | H16: =IF($D16=$H$3,$E16,0) -> 0
C17: First aid box | D17: Y | E17: 1 | F17: =IF(D17="NA",E17,0) -> 0 | G17: =IF(D17=$G$3,E17,0) -> 1 | H17: =IF($D17=$H$3,$E17,0) -> 0
A19: 3 | B19: Power room | C19: Fire Extingusher: Cleanliness/Location | D19: N | E19: 3 | F19: =IF($D19=$F$3,$E19,0) -> 0 | G19: =IF(D19=$G$3,$E19,0) -> 0 | H19: =IF($D19=$H$3,$E19,0) -> 3 | I19: No marking | K19: =SUM(G19:G30)/SUM(G19:H30) -> 0.46666667
C20: Floor cleanliness | D20: Y | E20: 3 | F20: =IF(D20="NA",E20,0) -> 0 | G20: =IF(D20=$G$3,E20,0) -> 3 | H20: =IF($D20=$H$3,$E20,0) -> 0
C21: Wall cleanliness | D21: Y | E21: 2 | F21: =IF(D21="NA",E21,0) -> 0 | G21: =IF(D21=$G$3,E21,0) -> 2 | H21: =IF($D21=$H$3,$E21,0) -> 0
C22: Roof cleanliness | D22: Y | E22: 2 | F22: =IF(D22="NA",E22,0) -> 0 | G22: =IF(D22=$G$3,E22,0) -> 2 | H22: =IF($D22=$H$3,$E22,0) -> 0
C23: Seats | D23: N | E23: 3 | F23: =IF(D23="NA",E23,0) -> 0 | G23: =IF(D23=$G$3,E23,0) -> 0 | H23: =IF($D23=$H$3,$E23,0) -> 3 | I23: not in designated location.
C24: Door cleanliness | D24: N | E24: 2 | F24: =IF(D24="NA",E24,0) -> 0 | G24: =IF(D24=$G$3,E24,0) -> 0 | H24: =IF($D24=$H$3,$E24,0) -> 2 | I24: Dusty on the door
A32: 4 | B32: Power room | C32: Floor cleanliness | D32: N | E32: 3 | F32: =IF($D32=$F$3,$E32,0) -> 0 | G32: =IF(D32=$G$3,$E32,0) -> 0 | H32: =IF($D32=$H$3,$E32,0) -> 3 | I32: Dusty | K32: =SUM(G32:G43)/SUM(G32:H43) -> 0.2
C33: Wall cleanliness | D33: Y | E33: 2 | F33: =IF(D33="NA",E33,0) -> 0 | G33: =IF(D33=$G$3,E33,0) -> 2 | H33: =IF($D33=$H$3,$E33,0) -> 0
C34: Roof cleanliness | D34: N | E34: 2 | F34: =IF(D34="NA",E34,0) -> 0 | G34: =IF(D34=$G$3,E34,0) -> 0 | H34: =IF($D34=$H$3,$E34,0) -> 2 | I34: Dust,Spider web
C35: Lubricant | D35: N | E35: 3 | F35: =IF(D35="NA",E35,0) -> 0 | G35: =IF(D35=$G$3,E35,0) -> 0 | H35: =IF($D35=$H$3,$E35,0) -> 3 | I35: Should put porperly or mark it.
A45: 4 | B45: Archive room | C45: Documents | D45: N | E45: 4 | F45: =IF($D45=$F$3,$E45,0) -> 0 | G45: =IF(D45=$G$3,$E45,0) -> 0 | H45: =IF($D45=$H$3,$E45,0) -> 4 | I45: Not orgarnized | K45: =SUM(G45:G56)/SUM(G45:H56) -> 0.6
C46: Light | D46: Y | E46: 2 | F46: =IF(D46="NA",E46,0) -> 0 | G46: =IF(D46=$G$3,E46,0) -> 2 | H46: =IF($D46=$H$3,$E46,0) -> 0
C47: Floor cleanliness | D47: Y | E47: 3 | F47: =IF(D47="NA",E47,0) -> 0 | G47: =IF(D47=$G$3,E47,0) -> 3 | H47: =IF($D47=$H$3,$E47,0) -> 0
C48: Wall cleanliness | D48: Y | E48: 2 | F48: =IF(D48="NA",E48,0) -> 0 | G48: =IF(D48=$G$3,E48,0) -> 2 | H48: =IF($D48=$H$3,$E48,0) -> 0
C49: Roof cleanliness | D49: Y | E49: 2 | F49: =IF($D49=$F$3,$E49,0) -> 0 | G49: =IF(D49=$G$3,$E49,0) -> 2 | H49: =IF($D49=$H$3,$E49,0) -> 0
C50: Othes | D50: N | E50: 2 | F50: =IF(D50="NA",E50,0) -> 0 | G50: =IF(D50=$G$3,E50,0) -> 0 | H50: =IF($D50=$H$3,$E50,0) -> 2 | I50: Stuffs kept block cabinet

Sheet Car washing, waste oil
A1: xx 5S Checklist: Car washing , waste oil storage | J1: Compliance:
A3: SL | B3: Location | C3: Description | D3: Y/N | F3: NA | G3: Y | H3: N | I3: Comments | J3: Picture | K3: Points
E5: =SUM(E6:E109) -> 88 | F5: =SUM(F6:F109) -> 3 | G5: =SUM(G6:G109) -> 73 | H5: =SUM(H6:H109) -> 12 | I5: =G5/(E5-F5) -> 0.85882353
A6: 1 | B6: Waste oil storage | C6: Oil drum: ESMS/Cleanliness | D6: Y | E6: 3 | F6: =IF($D6=$F$3,$E6,0) -> 0 | G6: =IF(D6=$G$3,$E6,0) -> 3 | H6: =IF($D6=$H$3,$E6,0) -> 0 | K6: =SUM(G6:G17)/SUM(G6:H17) -> 1
C7: Floor cleanliness | D7: Y | E7: 3 | F7: =IF(D7="NA",E7,0) -> 0 | G7: =IF(D7=$G$3,E7,0) -> 3 | H7: =IF($D7=$H$3,$E7,0) -> 0
C8: Free of Oil leaks/Spills | D8: Y | E8: 5 | F8: =IF(D8="NA",E8,0) -> 0 | G8: =IF(D8=$G$3,E8,0) -> 5 | H8: =IF($D8=$H$3,$E8,0) -> 0
C9: Wall cleanliness | D9: Y | E9: 2 | F9: =IF(D9="NA",E9,0) -> 0 | G9: =IF(D9=$G$3,E9,0) -> 2 | H9: =IF($D9=$H$3,$E9,0) -> 0
C10: Ceiling cleanliness | D10: Y | E10: 2 | F10: =IF(D10="NA",E10,0) -> 0 | G10: =IF(D10=$G$3,E10,0) -> 2 | H10: =IF($D10=$H$3,$E10,0) -> 0
C11: Other
L17: =K6 -> 1
A19: 2 | B19: Males locker room | C19: Locker: cleanliness | D19: Y | E19: 1 | F19: =IF($D19=$F$3,$E19,0) -> 0 | G19: =IF(D19=$G$3,$E19,0) -> 1 | H19: =IF($D19=$H$3,$E19,0) -> 0 | K19: =SUM(G19:G30)/SUM(G19:H30) -> 0.8
C20: Floor cleanliness | D20: Y | E20: 3 | F20: =IF(D20="NA",E20,0) -> 0 | G20: =IF(D20=$G$3,E20,0) -> 3 | H20: =IF($D20=$H$3,$E20,0) -> 0
C21: Window: cleanliness | D21: Y | E21: 2 | F21: =IF(D21="NA",E21,0) -> 0 | G21: =IF(D21=$G$3,E21,0) -> 2 | H21: =IF($D21=$H$3,$E21,0) -> 0
C22: Wall cleanliness | D22: N | E22: 2 | F22: =IF(D22="NA",E22,0) -> 0 | G22: =IF(D22=$G$3,E22,0) -> 0 | H22: =IF($D22=$H$3,$E22,0) -> 2 | I22: stain
C23: Ceiling cleanliness | D23: Y | E23: 2 | F23: =IF(D23="NA",E23,0) -> 0 | G23: =IF(D23=$G$3,E23,0) -> 2 | H23: =IF($D23=$H$3,$E23,0) -> 0
C24: Other
L30: =K19 -> 0.8
A32: 3 | B32: Males rest room | C32: Floor cleanliness | D32: Y | E32: 3 | F32: =IF($D32=$F$3,$E32,0) -> 0 | G32: =IF(D32=$G$3,$E32,0) -> 3 | H32: =IF($D32=$H$3,$E32,0) -> 0 | K32: =SUM(G32:G43)/SUM(G32:H43) -> 0.9
C33: Sink cleanliness | D33: N | E33: 1 | F33: =IF(D33="NA",E33,0) -> 0 | G33: =IF(D33=$G$3,E33,0) -> 0 | H33: =IF($D33=$H$3,$E33,0) -> 1 | I33: Stain
C34: Wall cleanliness | D34: Y | E34: 2 | F34: =IF(D34="NA",E34,0) -> 0 | G34: =IF(D34=$G$3,E34,0) -> 2 | H34: =IF($D34=$H$3,$E34,0) -> 0
C35: Ceiling cleanliness | D35: Y | E35: 2 | F35: =IF(D35="NA",E35,0) -> 0 | G35: =IF(D35=$G$3,E35,0) -> 2 | H35: =IF($D35=$H$3,$E35,0) -> 0
C36: Mirror cleanliness | D36: Y | E36: 2 | F36: =IF(D36="NA",E36,0) -> 0 | G36: =IF(D36=$G$3,E36,0) -> 2 | H36: =IF($D36=$H$3,$E36,0) -> 0
C37: Other
L43: =K32 -> 0.9
A45: 4 | B45: Outside | C45: Smoking area:Placement | D45: Y | E45: 1 | F45: =IF($D45=$F$3,$E45,0) -> 0 | G45: =IF(D45=$G$3,$E45,0) -> 1 | H45: =IF($D45=$H$3,$E45,0) -> 0 | K45: =SUM(G45:G56)/SUM(G45:H56) -> 0.16666667
C46: Floor cleanliness | D46: N | E46: 3 | F46: =IF(D46="NA",E46,0) -> 0 | G46: =IF(D46=$G$3,E46,0) -> 0 | H46: =IF($D46=$H$3,$E46,0) -> 3 | I46: Rust stain on the floor
C47: Wall cleanliness | D47: N | E47: 2 | F47: =IF(D47="NA",E47,0) -> 0 | G47: =IF(D47=$G$3,E47,0) -> 0 | H47: =IF($D47=$H$3,$E47,0) -> 2 | I47: stain
C48: Other | D48: NA | E48: 2 | F48: =IF(D48="NA",E48,0) -> 2 | G48: =IF(D48=$G$3,E48,0) -> 0 | H48: =IF($D48=$H$3,$E48,0) -> 0
A58: 5 | B58: Outside | C58: Floor cleanliness | D58: Y | E58: 3 | F58: =IF($D58=$F$3,$E58,0) -> 0 | G58: =IF(D58=$G$3,$E58,0) -> 3 | H58: =IF($D58=$H$3,$E58,0) -> 0 | K58: =SUM(G58:G69)/SUM(G58:H69) -> 0.71428571
C59: Wall cleanliness | D59: Y | E59: 2 | F59: =IF(D59="NA",E59,0) -> 0 | G59: =IF(D59=$G$3,E59,0) -> 2 | H59: =IF($D59=$H$3,$E59,0) -> 0
C60: Warranty Tire | D60: N | E60: 2 | F60: =IF(D60="NA",E60,0) -> 0 | G60: =IF(D60=$G$3,E60,0) -> 0 | H60: =IF($D60=$H$3,$E60,0) -> 2 | I60: No warranty label
A71: 6 | B71: Outside (Near Water Tank) | C71: Floor cleanliness | D71: Y | E71: 3 | F71: =IF($D71=$F$3,$E71,0) -> 0 | G71: =IF(D71=$G$3,$E71,0) -> 3 | H71: =IF($D71=$H$3,$E71,0) -> 0 | K71: =SUM(G71:G82)/SUM(G71:H82) -> 1
C72: Wall cleanliness | D72: Y | E72: 2 | F72: =IF(D72="NA",E72,0) -> 0 | G72: =IF(D72=$G$3,E72,0) -> 2 | H72: =IF($D72=$H$3,$E72,0) -> 0
C73: Water tank: cleanliness | D73: Y | E73: 3 | F73: =IF(D73="NA",E73,0) -> 0 | G73: =IF(D73=$G$3,E73,0) -> 3 | H73: =IF($D73=$H$3,$E73,0) -> 0
C74: Power distributor | D74: Y | E74: 1 | F74: =IF(D74="NA",E74,0) -> 0 | G74: =IF(D74=$G$3,E74,0) -> 1 | H74: =IF($D74=$H$3,$E74,0) -> 0
L82: =SUM(K45:K82)/3 -> 0.62698413
A84: 6 | B84: Car washing | C84: Washing machine:Placement | D84: NA | E84: 1 | F84: =IF($D84=$F$3,$E84,0) -> 1 | G84: =IF(D84=$G$3,$E84,0) -> 0 | H84: =IF($D84=$H$3,$E84,0) -> 0 | K84: =SUM(G84:G95)/SUM(G84:H95) -> 0.85714286
C85: Air hose: Placement | D85: Y | E85: 1 | F85: =IF(D85="NA",E85,0) -> 0 | G85: =IF(D85=$G$3,E85,0) -> 1 | H85: =IF($D85=$H$3,$E85,0) -> 0
C86: Floor cleanliness | D86: Y | E86: 3 | F86: =IF(D86="NA",E86,0) -> 0 | G86: =IF(D86=$G$3,E86,0) -> 3 | H86: =IF($D86=$H$3,$E86,0) -> 0
C87: Window cleanliness | D87: Y | E87: 2 | F87: =IF(D87="NA",E87,0) -> 0 | G87: =IF(D87=$G$3,E87,0) -> 2 | H87: =IF($D87=$H$3,$E87,0) -> 0
...

Sheet WSC Room
A1: xx Branch 5S Checklist: WSC, Unit Recondition, Power Room, Archive Room, Training Room | J1: Compliance:
A3: SL | B3: Location | C3: Description | D3: Y/N | F3: NA | G3: Y | H3: N | I3: Comments | J3: Picture | K3: Points
E5: =SUM(E6:E187) -> 89 | F5: =SUM(F6:F187) -> 10 | G5: =SUM(G6:G187) -> 57 | H5: =SUM(H6:H187) -> 16 | I5: =G5/(E5-F5) -> 0.72151899
A6: 1 | B6: Workshop Control Room | C6: Documents | D6: Y | E6: 2 | F6: =IF($D6=$F$3,$E6,0) -> 0 | G6: =IF(D6=$G$3,$E6,0) -> 2 | H6: =IF($D6=$H$3,$E6,0) -> 0 | K6: =SUM(G6:G17)/SUM(G6:H17) -> 0.82352941
C7: Chairs | D7: Y | E7: 1 | F7: =IF(D7="NA",E7,0) -> 0 | G7: =IF(D7=$G$3,E7,0) -> 1 | H7: =IF($D7=$H$3,$E7,0) -> 0
C8: Desk | D8: Y | E8: 2 | F8: =IF(D8="NA",E8,0) -> 0 | G8: =IF(D8=$G$3,E8,0) -> 2 | H8: =IF($D8=$H$3,$E8,0) -> 0
C9: Door cleanliness | D9: Y | E9: 2 | F9: =IF(D9="NA",E9,0) -> 0 | G9: =IF(D9=$G$3,E9,0) -> 2 | H9: =IF($D9=$H$3,$E9,0) -> 0
C10: Floor cleanliness | D10: Y | E10: 3 | F10: =IF(D10="NA",E10,0) -> 0 | G10: =IF(D10=$G$3,E10,0) -> 3 | H10: =IF($D10=$H$3,$E10,0) -> 0
C11: Wall cleanliness | D11: N | E11: 2 | F11: =IF(D11="NA",E11,0) -> 0 | G11: =IF(D11=$G$3,E11,0) -> 0 | H11: =IF($D11=$H$3,$E11,0) -> 2 | I11: stain inside/outside
C12: Ceiling cleanliness | D12: Y | E12: 2 | F12: =IF(D12="NA",E12,0) -> 0 | G12: =IF(D12=$G$3,E12,0) -> 2 | H12: =IF($D12=$H$3,$E12,0) -> 0
C13: First aid box | D13: Y | E13: 2 | F13: =IF(D13="NA",E13,0) -> 0 | G13: =IF(D13=$G$3,E13,0) -> 2 | H13: =IF($D13=$H$3,$E13,0) -> 0
C14: Other | D14: N | E14: 1 | F14: =IF(D14="NA",E14,0) -> 0 | G14: =IF(D14=$G$3,E14,0) -> 0 | H14: =IF($D14=$H$3,$E14,0) -> 1 | I14: Warranty parts kept in the room
L17: =K6 -> 0.82352941
A19: 2 | B19: Unit recondition room | C19: Workbench | D19: Y | E19: 1 | F19: =IF($D19=$F$3,$E19,0) -> 0 | G19: =IF(D19=$G$3,$E19,0) -> 1 | H19: =IF($D19=$H$3,$E19,0) -> 0 | K19: =SUM(G19:G30)/SUM(G19:H30) -> 0.70588235
C20: Floor cleanliness | D20: Y | E20: 3 | F20: 0 | G20: 0 | H20: 3
C21: Free of Oil leaks/Spills | D21: Y | E21: 5 | F21: =IF(D21="NA",E21,0) -> 0 | G21: =IF(D21=$G$3,E21,0) -> 5 | H21: =IF($D21=$H$3,$E21,0) -> 0
C22: Unidentified parts | D22: NA | E22: 2 | F22: 0 | G22: 0 | H22: =IF($D22=$H$3,$E22,0) -> 0
C23: Tools/equipment: Placement | D23: NA | E23: 2 | F23: 0 | G23: 0 | H23: =IF($D23=$H$3,$E23,0) -> 0
C24: Tool racks | D24: NA | E24: 2 | F24: 0 | G24: 0 | H24: =IF($D24=$H$3,$E24,0) -> 0
C25: Wall Cleanliness | D25: Y | E25: 2 | F25: =IF(D25="NA",E25,0) -> 0 | G25: =IF(D25=$G$3,E25,0) -> 2 | H25: =IF($D25=$H$3,$E25,0) -> 0
C26: Ceiling cleanliness | D26: Y | E26: 2 | F26: =IF(D26="NA",E26,0) -> 0 | G26: =IF(D26=$G$3,E26,0) -> 2 | H26: =IF($D26=$H$3,$E26,0) -> 0
C27: Power distributor | D27: Y | E27: 2 | F27: =IF(D27="NA",E27,0) -> 0 | G27: =IF(D27=$G$3,E27,0) -> 2 | H27: =IF($D27=$H$3,$E27,0) -> 0
C28: Other | D28: N | E28: 2 | F28: =IF(D28="NA",E28,0) -> 0 | G28: =IF(D28=$G$3,E28,0) -> 0 | H28: =IF($D28=$H$3,$E28,0) -> 2 | I28: old clothes not in designated location
L30: =K19 -> 0.70588235
A32: 3 | B32: Tool Room | C32: Tool Preparation | D32: Y | E32: 5 | F32: =IF(D32="NA",E32,0) -> 0 | G32: =IF(D32=$G$3,E32,0) -> 5 | H32: =IF($D32=$H$3,$E32,0) -> 0 | K32: =SUM(G32:G43)/SUM(G32:H43) -> 1
C33: Tool Inventory Check List | D33: Y | E33: 3 | F33: =IF(D33="NA",E33,0) -> 0 | G33: =IF(D33=$G$3,E33,0) -> 3 | H33: =IF($D33=$H$3,$E33,0) -> 0
C34: Floor cleanliness | D34: Y | E34: 3 | F34: =IF(D34="NA",E34,0) -> 0 | G34: =IF(D34=$G$3,E34,0) -> 3 | H34: =IF($D34=$H$3,$E34,0) -> 0
C35: Wall Cleanliness | D35: Y | E35: 2 | F35: =IF(D35="NA",E35,0) -> 0 | G35: =IF(D35=$G$3,E35,0) -> 2 | H35: =IF($D35=$H$3,$E35,0) -> 0
C36: Ceiling cleanliness | D36: Y | E36: 2 | F36: =IF(D36="NA",E36,0) -> 0 | G36: =IF(D36=$G$3,E36,0) -> 2 | H36: =IF($D36=$H$3,$E36,0) -> 0
L43: =K32 -> 1
A45: 4 | B45: Archive room | C45: Document racks:Placement | D45: Y | E45: 1 | F45: =IF($D45=$F$3,$E45,0) -> 0 | G45: =IF(D45=$G$3,$E45,0) -> 1 | H45: =IF($D45=$H$3,$E45,0) -> 0 | K45: =SUM(G45:G56)/SUM(G45:H56) -> 0.81818182
C46: Documents: Put properly | D46: Y | E46: 3 | F46: =IF(D46="NA",E46,0) -> 0 | G46: =IF(D46=$G$3,E46,0) -> 3 | H46: =IF($D46=$H$3,$E46,0) -> 0
C47: Floor cleanliness | D47: Y | E47: 3 | F47: =IF(D47="NA",E47,0) -> 0 | G47: =IF(D47=$G$3,E47,0) -> 3 | H47: =IF($D47=$H$3,$E47,0) -> 0
C48: Wall cleanliness | D48: N | E48: 2 | F48: =IF(D48="NA",E48,0) -> 0 | G48: =IF(D48=$G$3,E48,0) -> 0 | H48: =IF($D48=$H$3,$E48,0) -> 2 | I48: spider web
C49: Ceiling cleanliness | D49: Y | E49: 2 | F49: =IF(D49="NA",E49,0) -> 0 | G49: =IF(D49=$G$3,E49,0) -> 2 | H49: =IF($D49=$H$3,$E49,0) -> 0
L56: =K45 -> 0.81818182
A58: 5 | B58: Training room | C58: Chairs: Put properly | D58: N | E58: 1 | F58: =IF($D58=$F$3,$E58,0) -> 0 | G58: =IF(D58=$G$3,$E58,0) -> 0 | H58: =IF($D58=$H$3,$E58,0) -> 1 | I58: put not properly | K58: =SUM(G58:G69)/SUM(G58:H69) -> 0.53846154
C59: Floor cleanliness | D59: Y | E59: 3 | F59: =IF(D59="NA",E59,0) -> 0 | G59: =IF(D59=$G$3,E59,0) -> 3 | H59: =IF($D59=$H$3,$E59,0) -> 0
C60: Wall cleanliness | D60: Y | E60: 2 | F60: =IF(D60="NA",E60,0) -> 0 | G60: =IF(D60=$G$3,E60,0) -> 2 | H60: =IF($D60=$H$3,$E60,0) -> 0
C61: Ceiling cleanliness | D61: Y | E61: 2 | F61: =IF(D61="NA",E61,0) -> 0 | G61: =IF(D61=$G$3,E61,0) -> 2 | H61: =IF($D61=$H$3,$E61,0) -> 0
...

Sheet Parts, Warranty
A1: xx Branch 5S Checklist: Parts Department, Warranty Room | J1: Compliance: | K1: =I5 -> 0.75438596
A3: SL | B3: Location | C3: Description | D3: Y/N | F3: NA | G3: Y | H3: N | I3: Comments | J3: Picture | K3: Points
E5: =SUM(E7:E57) -> 67 | F5: =SUM(F7:F57) -> 10 | G5: =SUM(G7:G57) -> 43 | H5: =SUM(H7:H57) -> 14 | I5: =G5/(E5-F5) -> 0.75438596
A7: 1 | B7: Warehouse | C7: Fire Extingusher: Cleanliness/Location | D7: Y | E7: 3 | F7: =IF($D7=$F$3,$E7,0) -> 0 | G7: =IF(D7=$G$3,$E7,0) -> 3 | H7: =IF($D7=$H$3,$E7,0) -> 0 | K7: =SUM(G7:G18)/SUM(G7:H18) -> 0.90909091
C8: Trolley Jack | D8: Y | E8: 1 | F8: =IF(D8="NA",E8,0) -> 0 | G8: =IF(D8=$G$3,E8,0) -> 1 | H8: =IF($D8=$H$3,$E8,0) -> 0
