Workbook

Sheet Summary
A1: AR summary – Quick Lane (Co 26 basis, USD)
A2: As-of date | B2: 46318
A4: Account | B4: Name | C4: Open docs | D4: Open ($) | E4: Overdue ($) | F4: Over 90 days ($) | G4: Paid, not posted (docs) | H4: Paid, not posted ($)
A5: B0002 | B5: Lao Brewery Co., Ltd (Beerlao) | C5: =COUNTIFS('AR Open'!$A$2:$A$277,A5) -> 165 | D5: =SUMIFS('AR Open'!$I$2:$I$277,'AR Open'!$A$2:$A$277,A5) -> 62449.03 | E5: =SUMIFS('AR Open'!$I$2:$I$277,'AR Open'!$A$2:$A$277,A5,'AR Open'!$J$2:$J$277,">0") -> 45270.56 | F5: =SUMIFS('AR Open'!$I$2:$I$277,'AR Open'!$A$2:$A$277,A5,'AR Open'!$K$2:$K$277,"90+") -> 27495.76 | G5: =COUNTIFS('Paid - CR match'!$A$4:$A$49,A5) -> 1 | H5: =SUMIFS('Paid - CR match'!$G$4:$G$49,'Paid - CR match'!$A$4:$A$49,A5) -> 76.95
A6: P0009 | B6: Phubia Mining | C6: =COUNTIFS('AR Open'!$A$2:$A$277,A6) -> 28 | D6: =SUMIFS('AR Open'!$I$2:$I$277,'AR Open'!$A$2:$A$277,A6) -> 24266.33 | E6: =SUMIFS('AR Open'!$I$2:$I$277,'AR Open'!$A$2:$A$277,A6,'AR Open'!$J$2:$J$277,">0") -> 792.98 | F6: =SUMIFS('AR Open'!$I$2:$I$277,'AR Open'!$A$2:$A$277,A6,'AR Open'!$K$2:$K$277,"90+") -> -118 | G6: =COUNTIFS('Paid - CR match'!$A$4:$A$49,A6) -> 42 | H6: =SUMIFS('Paid - CR match'!$G$4:$G$49,'Paid - CR match'!$A$4:$A$49,A6) -> 23766.86
A7: V0197 | C7: =COUNTIFS('AR Open'!$A$2:$A$277,A7) -> 8 | D7: =SUMIFS('AR Open'!$I$2:$I$277,'AR Open'!$A$2:$A$277,A7) -> 6482.32 | E7: =SUMIFS('AR Open'!$I$2:$I$277,'AR Open'!$A$2:$A$277,A7,'AR Open'!$J$2:$J$277,">0") -> 0 | F7: =SUMIFS('AR Open'!$I$2:$I$277,'AR Open'!$A$2:$A$277,A7,'AR Open'!$K$2:$K$277,"90+") -> 0 | G7: =COUNTIFS('Paid - CR match'!$A$4:$A$49,A7) -> 0 | H7: =SUMIFS('Paid - CR match'!$G$4:$G$49,'Paid - CR match'!$A$4:$A$49,A7) -> 0
A8: I0021 | C8: =COUNTIFS('AR Open'!$A$2:$A$277,A8) -> 1 | D8: =SUMIFS('AR Open'!$I$2:$I$277,'AR Open'!$A$2:$A$277,A8) -> 4956.19 | E8: =SUMIFS('AR Open'!$I$2:$I$277,'AR Open'!$A$2:$A$277,A8,'AR Open'!$J$2:$J$277,">0") -> 0 | F8: =SUMIFS('AR Open'!$I$2:$I$277,'AR Open'!$A$2:$A$277,A8,'AR Open'!$K$2:$K$277,"90+") -> 0 | G8: =COUNTIFS('Paid - CR match'!$A$4:$A$49,A8) -> 0 | H8: =SUMIFS('Paid - CR match'!$G$4:$G$49,'Paid - CR match'!$A$4:$A$49,A8) -> 0
A9: B0010 | B9: Burapha Agro Forestry | C9: =COUNTIFS('AR Open'!$A$2:$A$277,A9) -> 8 | D9: =SUMIFS('AR Open'!$I$2:$I$277,'AR Open'!$A$2:$A$277,A9) -> 3583.47 | E9: =SUMIFS('AR Open'!$I$2:$I$277,'AR Open'!$A$2:$A$277,A9,'AR Open'!$J$2:$J$277,">0") -> 1235.25 | F9: =SUMIFS('AR Open'!$I$2:$I$277,'AR Open'!$A$2:$A$277,A9,'AR Open'!$K$2:$K$277,"90+") -> 1235.25 | G9: =COUNTIFS('Paid - CR match'!$A$4:$A$49,A9) -> 3 | H9: =SUMIFS('Paid - CR match'!$G$4:$G$49,'Paid - CR match'!$A$4:$A$49,A9) -> 288.7
A10: M0610 | B10: Mekong Timber Plantations | C10: =COUNTIFS('AR Open'!$A$2:$A$277,A10) -> 6 | D10: =SUMIFS('AR Open'!$I$2:$I$277,'AR Open'!$A$2:$A$277,A10) -> 2368.46 | E10: =SUMIFS('AR Open'!$I$2:$I$277,'AR Open'!$A$2:$A$277,A10,'AR Open'!$J$2:$J$277,">0") -> 2014.31 | F10: =SUMIFS('AR Open'!$I$2:$I$277,'AR Open'!$A$2:$A$277,A10,'AR Open'!$K$2:$K$277,"90+") -> -67.41 | G10: =COUNTIFS('Paid - CR match'!$A$4:$A$49,A10) -> 0 | H10: =SUMIFS('Paid - CR match'!$G$4:$G$49,'Paid - CR match'!$A$4:$A$49,A10) -> 0
A11: E0089 | C11: =COUNTIFS('AR Open'!$A$2:$A$277,A11) -> 6 | D11: =SUMIFS('AR Open'!$I$2:$I$277,'AR Open'!$A$2:$A$277,A11) -> 1843.12 | E11: =SUMIFS('AR Open'!$I$2:$I$277,'AR Open'!$A$2:$A$277,A11,'AR Open'!$J$2:$J$277,">0") -> 278.68 | F11: =SUMIFS('AR Open'!$I$2:$I$277,'AR Open'!$A$2:$A$277,A11,'AR Open'!$K$2:$K$277,"90+") -> 0 | G11: =COUNTIFS('Paid - CR match'!$A$4:$A$49,A11) -> 0 | H11: =SUMIFS('Paid - CR match'!$G$4:$G$49,'Paid - CR match'!$A$4:$A$49,A11) -> 0
A12: B0137 | B12: TPLUS Digital Sole Co., Ltd (Vimpelcom Lao) | C12: =COUNTIFS('AR Open'!$A$2:$A$277,A12) -> 3 | D12: =SUMIFS('AR Open'!$I$2:$I$277,'AR Open'!$A$2:$A$277,A12) -> 1754.07 | E12: =SUMIFS('AR Open'!$I$2:$I$277,'AR Open'!$A$2:$A$277,A12,'AR Open'!$J$2:$J$277,">0") -> 1662.33 | F12: =SUMIFS('AR Open'!$I$2:$I$277,'AR Open'!$A$2:$A$277,A12,'AR Open'!$K$2:$K$277,"90+") -> 0 | G12: =COUNTIFS('Paid - CR match'!$A$4:$A$49,A12) -> 0 | H12: =SUMIFS('Paid - CR match'!$G$4:$G$49,'Paid - CR match'!$A$4:$A$49,A12) -> 0
A13: C0006 | B13: Cash Sale QL | C13: =COUNTIFS('AR Open'!$A$2:$A$277,A13) -> 10 | D13: =SUMIFS('AR Open'!$I$2:$I$277,'AR Open'!$A$2:$A$277,A13) -> 1158.4 | E13: =SUMIFS('AR Open'!$I$2:$I$277,'AR Open'!$A$2:$A$277,A13,'AR Open'!$J$2:$J$277,">0") -> 1158.4 | F13: =SUMIFS('AR Open'!$I$2:$I$277,'AR Open'!$A$2:$A$277,A13,'AR Open'!$K$2:$K$277,"90+") -> -78.09 | G13: =COUNTIFS('Paid - CR match'!$A$4:$A$49,A13) -> 0 | H13: =SUMIFS('Paid - CR match'!$G$4:$G$49,'Paid - CR match'!$A$4:$A$49,A13) -> 0
A14: A0238 | C14: =COUNTIFS('AR Open'!$A$2:$A$277,A14) -> 3 | D14: =SUMIFS('AR Open'!$I$2:$I$277,'AR Open'!$A$2:$A$277,A14) -> 1133.08 | E14: =SUMIFS('AR Open'!$I$2:$I$277,'AR Open'!$A$2:$A$277,A14,'AR Open'!$J$2:$J$277,">0") -> 1133.08 | F14: =SUMIFS('AR Open'!$I$2:$I$277,'AR Open'!$A$2:$A$277,A14,'AR Open'!$K$2:$K$277,"90+") -> 1133.08 | G14: =COUNTIFS('Paid - CR match'!$A$4:$A$49,A14) -> 0 | H14: =SUMIFS('Paid - CR match'!$G$4:$G$49,'Paid - CR match'!$A$4:$A$49,A14) -> 0
A15: U0006 | B15: UXO Lao | C15: =COUNTIFS('AR Open'!$A$2:$A$277,A15) -> 6 | D15: =SUMIFS('AR Open'!$I$2:$I$277,'AR Open'!$A$2:$A$277,A15) -> 1042.67 | E15: =SUMIFS('AR Open'!$I$2:$I$277,'AR Open'!$A$2:$A$277,A15,'AR Open'!$J$2:$J$277,">0") -> 0 | F15: =SUMIFS('AR Open'!$I$2:$I$277,'AR Open'!$A$2:$A$277,A15,'AR Open'!$K$2:$K$277,"90+") -> 0 | G15: =COUNTIFS('Paid - CR match'!$A$4:$A$49,A15) -> 0 | H15: =SUMIFS('Paid - CR match'!$G$4:$G$49,'Paid - CR match'!$A$4:$A$49,A15) -> 0
A16: M0662 | B16: Mascot International - Lao Sole Co. Ltd | C16: =COUNTIFS('AR Open'!$A$2:$A$277,A16) -> 5 | D16: =SUMIFS('AR Open'!$I$2:$I$277,'AR Open'!$A$2:$A$277,A16) -> 906.03 | E16: =SUMIFS('AR Open'!$I$2:$I$277,'AR Open'!$A$2:$A$277,A16,'AR Open'!$J$2:$J$277,">0") -> 0 | F16: =SUMIFS('AR Open'!$I$2:$I$277,'AR Open'!$A$2:$A$277,A16,'AR Open'!$K$2:$K$277,"90+") -> 0 | G16: =COUNTIFS('Paid - CR match'!$A$4:$A$49,A16) -> 0 | H16: =SUMIFS('Paid - CR match'!$G$4:$G$49,'Paid - CR match'!$A$4:$A$49,A16) -> 0
A17: C0038 | B17: Comin Laos Sole PTE | C17: =COUNTIFS('AR Open'!$A$2:$A$277,A17) -> 13 | D17: =SUMIFS('AR Open'!$I$2:$I$277,'AR Open'!$A$2:$A$277,A17) -> 413.13 | E17: =SUMIFS('AR Open'!$I$2:$I$277,'AR Open'!$A$2:$A$277,A17,'AR Open'!$J$2:$J$277,">0") -> -1297.41 | F17: =SUMIFS('AR Open'!$I$2:$I$277,'AR Open'!$A$2:$A$277,A17,'AR Open'!$K$2:$K$277,"90+") -> -2060.81 | G17: =COUNTIFS('Paid - CR match'!$A$4:$A$49,A17) -> 0 | H17: =SUMIFS('Paid - CR match'!$G$4:$G$49,'Paid - CR match'!$A$4:$A$49,A17) -> 0
A18: B0205 | C18: =COUNTIFS('AR Open'!$A$2:$A$277,A18) -> 2 | D18: =SUMIFS('AR Open'!$I$2:$I$277,'AR Open'!$A$2:$A$277,A18) -> 387.62 | E18: =SUMIFS('AR Open'!$I$2:$I$277,'AR Open'!$A$2:$A$277,A18,'AR Open'!$J$2:$J$277,">0") -> 0 | F18: =SUMIFS('AR Open'!$I$2:$I$277,'AR Open'!$A$2:$A$277,A18,'AR Open'!$K$2:$K$277,"90+") -> 0 | G18: =COUNTIFS('Paid - CR match'!$A$4:$A$49,A18) -> 0 | H18: =SUMIFS('Paid - CR match'!$G$4:$G$49,'Paid - CR match'!$A$4:$A$49,A18) -> 0
A19: L0033 | C19: =COUNTIFS('AR Open'!$A$2:$A$277,A19) -> 3 | D19: =SUMIFS('AR Open'!$I$2:$I$277,'AR Open'!$A$2:$A$277,A19) -> 296.16 | E19: =SUMIFS('AR Open'!$I$2:$I$277,'AR Open'!$A$2:$A$277,A19,'AR Open'!$J$2:$J$277,">0") -> 185.06 | F19: =SUMIFS('AR Open'!$I$2:$I$277,'AR Open'!$A$2:$A$277,A19,'AR Open'!$K$2:$K$277,"90+") -> 0 | G19: =COUNTIFS('Paid - CR match'!$A$4:$A$49,A19) -> 0 | H19: =SUMIFS('Paid - CR match'!$G$4:$G$49,'Paid - CR match'!$A$4:$A$49,A19) -> 0
A20: G0096 | C20: =COUNTIFS('AR Open'!$A$2:$A$277,A20) -> 1 | D20: =SUMIFS('AR Open'!$I$2:$I$277,'AR Open'!$A$2:$A$277,A20) -> 256.56 | E20: =SUMIFS('AR Open'!$I$2:$I$277,'AR Open'!$A$2:$A$277,A20,'AR Open'!$J$2:$J$277,">0") -> 0 | F20: =SUMIFS('AR Open'!$I$2:$I$277,'AR Open'!$A$2:$A$277,A20,'AR Open'!$K$2:$K$277,"90+") -> 0 | G20: =COUNTIFS('Paid - CR match'!$A$4:$A$49,A20) -> 0 | H20: =SUMIFS('Paid - CR match'!$G$4:$G$49,'Paid - CR match'!$A$4:$A$49,A20) -> 0
A21: V0006 | C21: =COUNTIFS('AR Open'!$A$2:$A$277,A21) -> 2 | D21: =SUMIFS('AR Open'!$I$2:$I$277,'AR Open'!$A$2:$A$277,A21) -> 135.3 | E21: =SUMIFS('AR Open'!$I$2:$I$277,'AR Open'!$A$2:$A$277,A21,'AR Open'!$J$2:$J$277,">0") -> 135.3 | F21: =SUMIFS('AR Open'!$I$2:$I$277,'AR Open'!$A$2:$A$277,A21,'AR Open'!$K$2:$K$277,"90+") -> 61.6 | G21: =COUNTIFS('Paid - CR match'!$A$4:$A$49,A21) -> 0 | H21: =SUMIFS('Paid - CR match'!$G$4:$G$49,'Paid - CR match'!$A$4:$A$49,A21) -> 0
A22: P0299 | C22: =COUNTIFS('AR Open'!$A$2:$A$277,A22) -> 2 | D22: =SUMIFS('AR Open'!$I$2:$I$277,'AR Open'!$A$2:$A$277,A22) -> 126.96 | E22: =SUMIFS('AR Open'!$I$2:$I$277,'AR Open'!$A$2:$A$277,A22,'AR Open'!$J$2:$J$277,">0") -> 0 | F22: =SUMIFS('AR Open'!$I$2:$I$277,'AR Open'!$A$2:$A$277,A22,'AR Open'!$K$2:$K$277,"90+") -> 0 | G22: =COUNTIFS('Paid - CR match'!$A$4:$A$49,A22) -> 0 | H22: =SUMIFS('Paid - CR match'!$G$4:$G$49,'Paid - CR match'!$A$4:$A$49,A22) -> 0
A23: L0406 | C23: =COUNTIFS('AR Open'!$A$2:$A$277,A23) -> 1 | D23: =SUMIFS('AR Open'!$I$2:$I$277,'AR Open'!$A$2:$A$277,A23) -> 121.48 | E23: =SUMIFS('AR Open'!$I$2:$I$277,'AR Open'!$A$2:$A$277,A23,'AR Open'!$J$2:$J$277,">0") -> 121.48 | F23: =SUMIFS('AR Open'!$I$2:$I$277,'AR Open'!$A$2:$A$277,A23,'AR Open'!$K$2:$K$277,"90+") -> 0 | G23: =COUNTIFS('Paid - CR match'!$A$4:$A$49,A23) -> 0 | H23: =SUMIFS('Paid - CR match'!$G$4:$G$49,'Paid - CR match'!$A$4:$A$49,A23) -> 0
A24: D0107 | C24: =COUNTIFS('AR Open'!$A$2:$A$277,A24) -> 1 | D24: =SUMIFS('AR Open'!$I$2:$I$277,'AR Open'!$A$2:$A$277,A24) -> 82.1 | E24: =SUMIFS('AR Open'!$I$2:$I$277,'AR Open'!$A$2:$A$277,A24,'AR Open'!$J$2:$J$277,">0") -> 0 | F24: =SUMIFS('AR Open'!$I$2:$I$277,'AR Open'!$A$2:$A$277,A24,'AR Open'!$K$2:$K$277,"90+") -> 0 | G24: =COUNTIFS('Paid - CR match'!$A$4:$A$49,A24) -> 0 | H24: =SUMIFS('Paid - CR match'!$G$4:$G$49,'Paid - CR match'!$A$4:$A$49,A24) -> 0
A25: A0186 | C25: =COUNTIFS('AR Open'!$A$2:$A$277,A25) -> 1 | D25: =SUMIFS('AR Open'!$I$2:$I$277,'AR Open'!$A$2:$A$277,A25) -> 67.83 | E25: =SUMIFS('AR Open'!$I$2:$I$277,'AR Open'!$A$2:$A$277,A25,'AR Open'!$J$2:$J$277,">0") -> 0 | F25: =SUMIFS('AR Open'!$I$2:$I$277,'AR Open'!$A$2:$A$277,A25,'AR Open'!$K$2:$K$277,"90+") -> 0 | G25: =COUNTIFS('Paid - CR match'!$A$4:$A$49,A25) -> 0 | H25: =SUMIFS('Paid - CR match'!$G$4:$G$49,'Paid - CR match'!$A$4:$A$49,A25) -> 0
A26: M0472 | C26: =COUNTIFS('AR Open'!$A$2:$A$277,A26) -> 0 | D26: =SUMIFS('AR Open'!$I$2:$I$277,'AR Open'!$A$2:$A$277,A26) -> 0 | E26: =SUMIFS('AR Open'!$I$2:$I$277,'AR Open'!$A$2:$A$277,A26,'AR Open'!$J$2:$J$277,">0") -> 0 | F26: =SUMIFS('AR Open'!$I$2:$I$277,'AR Open'!$A$2:$A$277,A26,'AR Open'!$K$2:$K$277,"90+") -> 0 | G26: =COUNTIFS('Paid - CR match'!$A$4:$A$49,A26) -> 0 | H26: =SUMIFS('Paid - CR match'!$G$4:$G$49,'Paid - CR match'!$A$4:$A$49,A26) -> 0
A27: C0179 | C27: =COUNTIFS('AR Open'!$A$2:$A$277,A27) -> 1 | D27: =SUMIFS('AR Open'!$I$2:$I$277,'AR Open'!$A$2:$A$277,A27) -> -4.65 | E27: =SUMIFS('AR Open'!$I$2:$I$277,'AR Open'!$A$2:$A$277,A27,'AR Open'!$J$2:$J$277,">0") -> -4.65 | F27: =SUMIFS('AR Open'!$I$2:$I$277,'AR Open'!$A$2:$A$277,A27,'AR Open'!$K$2:$K$277,"90+") -> -4.65 | G27: =COUNTIFS('Paid - CR match'!$A$4:$A$49,A27) -> 0 | H27: =SUMIFS('Paid - CR match'!$G$4:$G$49,'Paid - CR match'!$A$4:$A$49,A27) -> 0
A28: Total | C28: =SUM(C5:C27) -> 276 | D28: =SUM(D5:D27) -> 113825.66 | E28: =SUM(E5:E27) -> 52685.37 | F28: =SUM(F5:F27) -> 27596.73 | G28: =SUM(G5:G27) -> 46 | H28: =SUM(H5:H27) -> 24132.51
A30: Notes
A31: AVIS (A0010) is excluded from this report as requested (96 docs, $34,135.07 still in Supabase).
A32: Source: Supabase ql_ar_track (project operation), exported 23/10/2026. Amounts in USD as stored.
A33: Ledger checked today against pasted Autoline statements (Co 26 only): C0006, B0002, C0038, I0021, M0662, B0010, B0205, E0089, P0299, B0137, V0197, P0009. Other accounts last loaded 21/10.
A34: 'Paid, not posted' = Supabase says paid, Autoline still shows it open (finance must post the receipt). Match each to Suphutta (Kitty)'s CR email in column K of the 'Paid - CR match' sheet.
A35: Not Co 26 but still in Supabase: B0002 doc 227796 (-154.55) and B0010 doc 18740 (492.16). Not removed.
A36: Pending offsets in Autoline: M0662 6139281 / 6201131 (764.65); B0010 6139089 / 6201132 (89.38); P0009 6139106 / 6201133 (206.40) and 6138770 / 6201126 (671.50).

Sheet AR Open
A1: Account | B1: Name | C1: Document | D1: Type | E1: WIP | F1: Customer ref | G1: Doc date | H1: Due date | I1: Amount ($) | J1: Days overdue | K1: Aging | L1: AR comment | M1: Last seen
A2: A0186 | C2: 6138743 | D2: I | E2: 27500 | F2: BESTTELECO | G2: 46295 | H2: 46325 | I2: 67.83 | J2: =IF(H2="","",MAX(0,Summary!$B$2-H2)) -> 0 | K2: =IF(J2="","No due date",IF(J2=0,"Not due",IF(J2<=30,"1-30",IF(J2<=60,"31-60",IF(J2<=90,"61-90","90+"))))) -> Not due | L2: z | M2: 46316
A3: A0238 | C3: 16687 | D3: A | E3: 10692 | F3: 6116798 | G3: 45658 | H3: 45658 | I3: 954.08 | J3: =IF(H3="","",MAX(0,Summary!$B$2-H3)) -> 660 | K3: =IF(J3="","No due date",IF(J3=0,"Not due",IF(J3<=30,"1-30",IF(J3<=60,"31-60",IF(J3<=90,"61-90","90+"))))) -> 90+ | L3: Confirm with Sanya | Labor cost for Phubia Ming | M3: 46316
A4: A0238 | C4: 16688 | D4: A | E4: 17925 | F4: 6124133 | G4: 45658 | H4: 45658 | I4: 96 | J4: =IF(H4="","",MAX(0,Summary!$B$2-H4)) -> 660 | K4: =IF(J4="","No due date",IF(J4=0,"Not due",IF(J4<=30,"1-30",IF(J4<=60,"31-60",IF(J4<=90,"61-90","90+"))))) -> 90+ | L4: Confirm with Sanya | Labor cost for Phubia Ming | M4: 46316
A5: A0238 | C5: 16690 | D5: A | F5: 6123738 | G5: 45658 | H5: 45658 | I5: 83 | J5: =IF(H5="","",MAX(0,Summary!$B$2-H5)) -> 660 | K5: =IF(J5="","No due date",IF(J5=0,"Not due",IF(J5<=30,"1-30",IF(J5<=60,"31-60",IF(J5<=90,"61-90","90+"))))) -> 90+ | L5: Confirm with Sanya | Labor cost for Phubia Ming | M5: 46316
A6: B0002 | B6: Lao Brewery Co., Ltd (Beerlao) | C6: 6127519 | D6: I | E6: 20942 | F6: DO | G6: 45773 | H6: 45833 | I6: 684.24 | J6: =IF(H6="","",MAX(0,Summary!$B$2-H6)) -> 485 | K6: =IF(J6="","No due date",IF(J6=0,"Not due",IF(J6<=30,"1-30",IF(J6<=60,"31-60",IF(J6<=90,"61-90","90+"))))) -> 90+ | L6: àºàº³àºàºµà»àº­à»àº¥à»àº§àºà»àº²àºàºµà»àº­àº­àº­àº | M6: 46318
A7: B0002 | B7: Lao Brewery Co., Ltd (Beerlao) | C7: 6127567 | D7: I | E7: 21226 | F7: KM 12 THADEUA RD | G7: 45776 | H7: 45836 | I7: 1744.52 | J7: =IF(H7="","",MAX(0,Summary!$B$2-H7)) -> 482 | K7: =IF(J7="","No due date",IF(J7=0,"Not due",IF(J7<=30,"1-30",IF(J7<=60,"31-60",IF(J7<=90,"61-90","90+"))))) -> 90+ | L7: àºàº³àºàºµà»àº­à»àº¥à»àº§àºà»àº²àºàºµà»àº­àº­àº­àº | M7: 46318
A8: B0002 | B8: Lao Brewery Co., Ltd (Beerlao) | C8: 6127576 | D8: I | E8: 20850 | F8: DO | G8: 45776 | H8: 45836 | I8: 213.29 | J8: =IF(H8="","",MAX(0,Summary!$B$2-H8)) -> 482 | K8: =IF(J8="","No due date",IF(J8=0,"Not due",IF(J8<=30,"1-30",IF(J8<=60,"31-60",IF(J8<=90,"61-90","90+"))))) -> 90+ | L8: àºàº³àºàºµà»àº­à»àº¥à»àº§àºà»àº²àºàºµà»àº­àº­àº­àº | M8: 46318
A9: B0002 | B9: Lao Brewery Co., Ltd (Beerlao) | C9: 6127616 | D9: I | E9: 20947 | F9: KM 12 THADEUA RD | G9: 45777 | H9: 45837 | I9: 64.14 | J9: =IF(H9="","",MAX(0,Summary!$B$2-H9)) -> 481 | K9: =IF(J9="","No due date",IF(J9=0,"Not due",IF(J9<=30,"1-30",IF(J9<=60,"31-60",IF(J9<=90,"61-90","90+"))))) -> 90+ | L9: àºàº³àºàºµà»àº­à»àº¥à»àº§àºà»àº²àºàºµà»àº­àº­àº­àº | M9: 46318
A10: B0002 | B10: Lao Brewery Co., Ltd (Beerlao) | C10: 6127623 | D10: I | E10: 21055 | F10: KM 12 THADEUA RD | G10: 45777 | H10: 45837 | I10: 67.98 | J10: =IF(H10="","",MAX(0,Summary!$B$2-H10)) -> 481 | K10: =IF(J10="","No due date",IF(J10=0,"Not due",IF(J10<=30,"1-30",IF(J10<=60,"31-60",IF(J10<=90,"61-90","90+"))))) -> 90+ | L10: àºàº³àºàºµà»àº­à»àº¥à»àº§àºà»àº²àºàºµà»àº­àº­àº­àº | M10: 46318
A11: B0002 | B11: Lao Brewery Co., Ltd (Beerlao) | C11: 6127624 | D11: I | E11: 20889 | F11: KM 12 THADEUA RD | G11: 45777 | H11: 45837 | I11: 80.48 | J11: =IF(H11="","",MAX(0,Summary!$B$2-H11)) -> 481 | K11: =IF(J11="","No due date",IF(J11=0,"Not due",IF(J11<=30,"1-30",IF(J11<=60,"31-60",IF(J11<=90,"61-90","90+"))))) -> 90+ | L11: àºàº³àºàºµà»àº­à»àº¥à»àº§àºà»àº²àºàºµà»àº­àº­àº­àº | M11: 46318
A12: B0002 | B12: Lao Brewery Co., Ltd (Beerlao) | C12: 6127626 | D12: I | E12: 21053 | F12: KM 12 THADEUA RD | G12: 45777 | H12: 45837 | I12: 30.91 | J12: =IF(H12="","",MAX(0,Summary!$B$2-H12)) -> 481 | K12: =IF(J12="","No due date",IF(J12=0,"Not due",IF(J12<=30,"1-30",IF(J12<=60,"31-60",IF(J12<=90,"61-90","90+"))))) -> 90+ | L12: àºàº³àºàºµà»àº­à»àº¥à»àº§àºà»àº²àºàºµà»àº­àº­àº­àº | M12: 46318
A13: B0002 | B13: Lao Brewery Co., Ltd (Beerlao) | C13: 6127627 | D13: I | E13: 21125 | F13: KM 12 THADEUA RD | G13: 45777 | H13: 45837 | I13: 75.46 | J13: =IF(H13="","",MAX(0,Summary!$B$2-H13)) -> 481 | K13: =IF(J13="","No due date",IF(J13=0,"Not due",IF(J13<=30,"1-30",IF(J13<=60,"31-60",IF(J13<=90,"61-90","90+"))))) -> 90+ | L13: àºàº³àºàºµà»àº­à»àº¥à»àº§àºà»àº²àºàºµà»àº­àº­àº­àº | M13: 46318
A14: B0002 | B14: Lao Brewery Co., Ltd (Beerlao) | C14: 6127855 | D14: I | E14: 20893 | F14: KM 12 THADEUA RD | G14: 45797 | H14: 45857 | I14: 68.38 | J14: =IF(H14="","",MAX(0,Summary!$B$2-H14)) -> 461 | K14: =IF(J14="","No due date",IF(J14=0,"Not due",IF(J14<=30,"1-30",IF(J14<=60,"31-60",IF(J14<=90,"61-90","90+"))))) -> 90+ | L14: àºàº³àºàºµà»àº­à»àº¥à»àº§àºà»àº²àºàºµà»àº­àº­àº­àº | M14: 46318
A15: B0002 | B15: Lao Brewery Co., Ltd (Beerlao) | C15: 6127992 | D15: I | E15: 21947 | F15: BEERLAOBRE | G15: 45806 | H15: 45866 | I15: 62.54 | J15: =IF(H15="","",MAX(0,Summary!$B$2-H15)) -> 452 | K15: =IF(J15="","No due date",IF(J15=0,"Not due",IF(J15<=30,"1-30",IF(J15<=60,"31-60",IF(J15<=90,"61-90","90+"))))) -> 90+ | L15: àºàº³àºàºµà»àº­à»àº¥à»àº§àºà»àº²àºàºµà»àº­àº­àº­àº | M15: 46318
A16: B0002 | B16: Lao Brewery Co., Ltd (Beerlao) | C16: 6128006 | D16: I | E16: 21921 | F16: BEERLAOBRE | G16: 45807 | H16: 45867 | I16: 86.53 | J16: =IF(H16="","",MAX(0,Summary!$B$2-H16)) -> 451 | K16: =IF(J16="","No due date",IF(J16=0,"Not due",IF(J16<=30,"1-30",IF(J16<=60,"31-60",IF(J16<=90,"61-90","90+"))))) -> 90+ | L16: àºàº³àºàºµà»àº­à»àº¥à»àº§àºà»àº²àºàºµà»àº­àº­àº­àº | M16: 46318
A17: B0002 | B17: Lao Brewery Co., Ltd (Beerlao) | C17: 6128113 | D17: I | E17: 22000 | F17: JUELANDERS | G17: 45817 | H17: 45877 | I17: 74.97 | J17: =IF(H17="","",MAX(0,Summary!$B$2-H17)) -> 441 | K17: =IF(J17="","No due date",IF(J17=0,"Not due",IF(J17<=30,"1-30",IF(J17<=60,"31-60",IF(J17<=90,"61-90","90+"))))) -> 90+ | L17: àºàº³àºàºµà»àº­à»àº¥à»àº§àºà»àº²àºàºµà»àº­àº­àº­àº | M17: 46318
... A40: B0002 | B40: Lao Brewery Co., Ltd (Beerlao) | C40: 6129826 | D40: I | E40: 23552 | F40: SOULIDETH | G40: 45958 | H40: 46018 | I40: 864.05 | J40: =IF(H40="","",MAX(0,Summary!$B$2-H40)) -> 300 | K40: =IF(J40="","No due date",IF(J40=0,"Not due",IF(J40<=30,"1-30",IF(J40<=60,"31-60",IF(J40<=90,"61-90","90+"))))) -> 90+ | L40: àºàºµà»àº­àº«àº¼àº¸àºà»àºàº´àº6à»àºàº·àº­àº | M40: 46318
A41: B0002 | B41: Lao Brewery Co., Ltd (Beerlao) | C41: 227796 | D41: P | F41: RF25120102 | G41: 45995 | H41: 45995 | I41: -154.55 | J41: =IF(H41="","",MAX(0,Summary!$B$2-H41)) -> 323 | K41: =IF(J41="","No due date",IF(J41=0,"Not due",IF(J41<=30,"1-30",IF(J41<=60,"31-60",IF(J41<=90,"61-90","90+"))))) -> 90+ | M41: 46316
A42: B0002 | B42: Lao Brewery Co., Ltd (Beerlao) | C42: 6130317 | D42: I | E42: 23577 | F42: MR | G42: 45995 | H42: 46055 | I42: 3884.91 | J42: =IF(H42="","",MAX(0,Summary!$B$2-H42)) -> 263 | K42: =IF(J42="","No due date",IF(J42=0,"Not due",IF(J42<=30,"1-30",IF(J42<=60,"31-60",IF(J42<=90,"61-90","90+"))))) -> 90+ | L42: àºàº³àºàºµà»àº­à»àº¥à»àº§àºà»àº²àºàºµà»àº­àº­àº­àº | M42: 46318
A43: B0002 | B43: Lao Brewery Co., Ltd (Beerlao) | C43: 6130319 | D43: I | E43: 23803 | F43: MR CHANTHI | G43: 45995 | H43: 46055 | I43: 819.5 | J43: =IF(H43="","",MAX(0,Summary!$B$2-H43)) -> 263 | K43: =IF(J43="","No due date",IF(J43=0,"Not due",IF(J43<=30,"1-30",IF(J43<=60,"31-60",IF(J43<=90,"61-90","90+"))))) -> 90+ | L43: àºàºµà»àº­àº«àº¼àº¸àºà»àºàº´àº6à»àºàº·àº­àº | M43: 46318
A44: B0002 | B44: Lao Brewery Co., Ltd (Beerlao) | C44: 6130320 | D44: I | E44: 23576 | F44: BEERLAOBEW | G44: 45995 | H44: 46055 | I44: 433.52 | J44: =IF(H44="","",MAX(0,Summary!$B$2-H44)) -> 263 | K44: =IF(J44="","No due date",IF(J44=0,"Not due",IF(J44<=30,"1-30",IF(J44<=60,"31-60",IF(J44<=90,"61-90","90+"))))) -> 90+ | L44: àºàºµà»àº­àº«àº¼àº¸àºà»àºàº´àº6à»àºàº·àº­àº | M44: 46318
A45: B0002 | B45: Lao Brewery Co., Ltd (Beerlao) | C45: 6130430 | D45: I | E45: 24012 | F45: BEERLAOBEW | G45: 46000 | H45: 46060 | I45: 62.54 | J45: =IF(H45="","",MAX(0,Summary!$B$2-H45)) -> 258 | K45: =IF(J45="","No due date",IF(J45=0,"Not due",IF(J45<=30,"1-30",IF(J45<=60,"31-60",IF(J45<=90,"61-90","90+"))))) -> 90+ | L45: àºàº³àºàºµà»àº­à»àº¥à»àº§àºà»àº²àºàºµà»àº­àº­àº­àº | M45: 46318
A46: B0002 | B46: Lao Brewery Co., Ltd (Beerlao) | C46: 6130431 | D46: I | E46: 23569 | F46: BEERLAOBRE | G46: 46000 | H46: 46060 | I46: 74.97 | J46: =IF(H46="","",MAX(0,Summary!$B$2-H46)) -> 258 | K46: =IF(J46="","No due date",IF(J46=0,"Not due",IF(J46<=30,"1-30",IF(J46<=60,"31-60",IF(J46<=90,"61-90","90+"))))) -> 90+ | L46: àºàº³àºàºµà»àº­à»àº¥à»àº§àºà»àº²àºàºµà»àº­àº­àº­àº | M46: 46318
A47: B0002 | B47: Lao Brewery Co., Ltd (Beerlao) | C47: 6130432 | D47: I | E47: 23507 | F47: MR | G47: 46000 | H47: 46060 | I47: 75.46 | J47: =IF(H47="","",MAX(0,Summary!$B$2-H47)) -> 258 | K47: =IF(J47="","No due date",IF(J47=0,"Not due",IF(J47<=30,"1-30",IF(J47<=60,"31-60",IF(J47<=90,"61-90","90+"))))) -> 90+ | L47: àºàº³àºàºµà»àº­à»àº¥à»àº§àºà»àº²àºàºµà»àº­àº­àº­àº | M47: 46318
A48: B0002 | B48: Lao Brewery Co., Ltd (Beerlao) | C48: 6130433 | D48: I | E48: 23670 | F48: BEERLAO | G48: 46000 | H48: 46060 | I48: 19.8 | J48: =IF(H48="","",MAX(0,Summary!$B$2-H48)) -> 258 | K48: =IF(J48="","No due date",IF(J48=0,"Not due",IF(J48<=30,"1-30",IF(J48<=60,"31-60",IF(J48<=90,"61-90","90+"))))) -> 90+ | L48: àºàº³àºàºµà»àº­à»àº¥à»àº§àºà»àº²àºàºµà»àº­àº­àº­àº | M48: 46318
A49: B0002 | B49: Lao Brewery Co., Ltd (Beerlao) | C49: 6130434 | D49: I | E49: 23478 | F49: MR | G49: 46000 | H49: 46060 | I49: 74.97 | J49: =IF(H49="","",MAX(0,Summary!$B$2-H49)) -> 258 | K49: =IF(J49="","No due date",IF(J49=0,"Not due",IF(J49<=30,"1-30",IF(J49<=60,"31-60",IF(J49<=90,"61-90","90+"))))) -> 90+ | L49: àºàº³àºàºµà»àº­à»àº¥à»àº§àºà»àº²àºàºµà»àº­àº­àº­àº | M49: 46318
A50: B0002 | B50: Lao Brewery Co., Ltd (Beerlao) | C50: 6130435 | D50: I | E50: 22541 | F50: BEERLAO | G50: 46000 | H50: 46060 | I50: 151.14 | J50: =IF(H50="","",MAX(0,Summary!$B$2-H50)) -> 258 | K50: =IF(J50="","No due date",IF(J50=0,"Not due",IF(J50<=30,"1-30",IF(J50<=60,"31-60",IF(J50<=90,"61-90","90+"))))) -> 90+ | L50: àºàºµà»àº­àº«àº¼àº¸àºà»àºàº´àº6à»àºàº·àº­àº | M50: 46318
A51: B0002 | B51: Lao Brewery Co., Ltd (Beerlao) | C51: 6130436 | D51: I | E51: 24026 | F51: BEERLAOBRE | G51: 46000 | H51: 46060 | I51: 67.49 | J51: =IF(H51="","",MAX(0,Summary!$B$2-H51)) -> 258 | K51: =IF(J51="","No due date",IF(J51=0,"Not due",IF(J51<=30,"1-30",IF(J51<=60,"31-60",IF(J51<=90,"61-90","90+"))))) -> 90+ | L51: àºàº³àºàºµà»àº­à»àº¥à»àº§àºà»àº²àºàºµà»àº­àº­àº­àº | M51: 46318
A52: B0002 | B52: Lao Brewery Co., Ltd (Beerlao) | C52: 6130437 | D52: I | E52: 23949 | F52: KM 12 THADEUA RD | G52: 46000 | H52: 46060 | I52: 106.65 | J52: =IF(H52="","",MAX(0,Summary!$B$2-H52)) -> 258 | K52: =IF(J52="","No due date",IF(J52=0,"Not due",IF(J52<=30,"1-30",IF(J52<=60,"31-60",IF(J52<=90,"61-90","90+"))))) -> 90+ | L52: àºàº³àºàºµà»àº­à»àº¥à»àº§àºà»àº²àºàºµà»àº­àº­àº­àº | M52: 46318
A53: B0002 | B53: Lao Brewery Co., Ltd (Beerlao) | C53: 6130438 | D53: I | E53: 23806 | F53: BEERLAO | G53: 46000 | H53: 46060 | I53: 74.97 | J53: =IF(H53="","",MAX(0,Summary!$B$2-H53)) -> 258 | K53: =IF(J53="","No due date",IF(J53=0,"Not due",IF(J53<=30,"1-30",IF(J53<=60,"31-60",IF(J53<=90,"61-90","90+"))))) -> 90+ | L53: àºàºµà»àº­àº«àº¼àº¸àºà»àºàº´àº6à»àºàº·àº­àº | M53: 46318
... A172: B0010 | B172: Burapha Agro Forestry | C172: 6130651 | D172: I | E172: 24421 | F172: BURAPHAAGR | G172: 46007 | H172: 46037 | I172: 430.51 | J172: =IF(H172="","",MAX(0,Summary!$B$2-H172)) -> 281 | K172: =IF(J172="","No due date",IF(J172=0,"Not due",IF(J172<=30,"1-30",IF(J172<=60,"31-60",IF(J172<=90,"61-90","90+"))))) -> 90+ | L172: àºà»à»àºà»àº²àº | M172: 46318
A173: B0010 | B173: Burapha Agro Forestry | C173: 18740 | D173: A | F173: 6130426 | G173: 46143 | H173: 46143 | I173: 492.16 | J173: =IF(H173="","",MAX(0,Summary!$B$2-H173)) -> 175 | K173: =IF(J173="","No due date",IF(J173=0,"Not due",IF(J173<=30,"1-30",IF(J173<=60,"31-60",IF(J173<=90,"61-90","90+"))))) -> 90+ | L173: àºà»à»àºà»àº²àº | M173: 46318
A174: B0010 | B174: Burapha Agro Forestry | C174: 6138511 | D174: I | E174: 27411 | F174: SOMCHAI | G174: 46289 | H174: 46319 | I174: 551.19 | J174: =IF(H174="","",MAX(0,Summary!$B$2-H174)) -> 0 | K174: =IF(J174="","No due date",IF(J174=0,"Not due",IF(J174<=30,"1-30",IF(J174<=60,"31-60",IF(J174<=90,"61-90","90+"))))) -> Not due | L174: Will pay by due date | M174: 46318
A175: B0010 | B175: Burapha Agro Forestry | C175: 6138779 | D175: I | E175: 27459 | F175: BURAPHAAGR | G175: 46295 | H175: 46325 | I175: 1041.16 | J175: =IF(H175="","",MAX(0,Summary!$B$2-H175)) -> 0 | K175: =IF(J175="","No due date",IF(J175=0,"Not due",IF(J175<=30,"1-30",IF(J175<=60,"31-60",IF(J175<=90,"61-90","90+"))))) -> Not due | L175: Will pay by due date | M175: 46318
A176: B0010 | B176: Burapha Agro Forestry | C176: 6139074 | D176: I | E176: 27528 | F176: BURAPHAAGR | G176: 46303 | H176: 46333 | I176: 755.87 | J176: =IF(H176="","",MAX(0,Summary!$B$2-H176)) -> 0 | K176: =IF(J176="","No due date",IF(J176=0,"Not due",IF(J176<=30,"1-30",IF(J176<=60,"31-60",IF(J176<=90,"61-90","90+"))))) -> Not due | L176: Will pay by due date | M176: 46318
A177: B0010 | B177: Burapha Agro Forestry | C177: 6139089 | D177: I | E177: 27573 | F177: BURAPHAAGR | G177: 46304 | H177: 46334 | I177: 89.38 | J177: =IF(H177="","",MAX(0,Summary!$B$2-H177)) -> 0 | K177: =IF(J177="","No due date",IF(J177=0,"Not due",IF(J177<=30,"1-30",IF(J177<=60,"31-60",IF(J177<=90,"61-90","90+"))))) -> Not due | M177: 46318
A178: B0010 | B178: Burapha Agro Forestry | C178: 6201132 | D178: C | E178: 27573 | F178: BURAPHAAGR | G178: 46314 | H178: 46344 | I178: -89.38 | J178: =IF(H178="","",MAX(0,Summary!$B$2-H178)) -> 0 | K178: =IF(J178="","No due date",IF(J178=0,"Not due",IF(J178<=30,"1-30",IF(J178<=60,"31-60",IF(J178<=90,"61-90","90+"))))) -> Not due | M178: 46318
A179: B0137 | B179: TPLUS Digital Sole Co., Ltd (Vimpelcom Lao) | C179: 6137605 | D179: I | E179: 26370 | F179: 14 Lane Xang Ave., P | G179: 46265 | H179: 46295 | I179: 1662.33 | J179: =IF(H179="","",MAX(0,Summary!$B$2-H179)) -> 23 | K179: =IF(J179="","No due date",IF(J179=0,"Not due",IF(J179<=30,"1-30",IF(J179<=60,"31-60",IF(J179<=90,"61-90","90+"))))) -> 1-30 | L179: àºàº±àºàºà»à»àºà»àº²àº | M179: 46318
A180: B0137 | B180: TPLUS Digital Sole Co., Ltd (Vimpelcom Lao) | C180: 6138858 | D180: I | E180: 27381 | F180: 14 Lane Xang Ave., P | G180: 46297 | H180: 46356 | I180: 23.76 | J180: =IF(H180="","",MAX(0,Summary!$B$2-H180)) -> 0 | K180: =IF(J180="","No due date",IF(J180=0,"Not due",IF(J180<=30,"1-30",IF(J180<=60,"31-60",IF(J180<=90,"61-90","90+"))))) -> Not due | L180: àºà»àº²àºàºàº²àº¡àºàº¹à»àºàº | M180: 46318
...

Sheet Paid - CR match
A1: Paid per Supabase but still shown as open in Autoline (checked 23/10 against pasted ledgers). Docs not on the ledger are not listed. Kitty's CR emails are not readable by Claude: only 6138417 is matched.
A3: Account | B3: Name | C3: Document | D3: WIP | E3: Customer ref | F3: Doc date | G3: Amount ($) | H3: Status | I3: Paid date | J3: Payment evidence | K3: CR match (Suphutta/Kitty) | L3: Comment
A4: B0002 | B4: Lao Brewery Co., Ltd (Beerlao) | C4: 6131439 | D4: 24841 | E4: DO | F4: 46074 | G4: 76.95 | H4: paid (date) | I4: 46246 | J4: LDB-LAK LAK 1945405 [Deposit to bank On 8 2026.xlsx / 12-14] | K4: Check amount | L4: CR file LDB 12/08/2026 LAK 1,945,405 (~$86.27) is not $76.95: check if deposit covers other docs.
A5: B0010 | B5: Burapha Agro Forestry | C5: 6130649 | D5: 24420 | E5: MALLON | F5: 46007 | G5: 171.12 | H5: paid (date) | I5: 46063 | J5: JDB-LAK LAK 3790000 [Deposit to bank On 2-2- 2026.xlsx / Sheet7] | K5: Check CR no. | L5: CR file JDB 02/02/2026 LAK 3,790,000. Amount OK. No Kitty CR email number in system.
A6: B0010 | B6: Burapha Agro Forestry | C6: 6133365 | D6: 23615 | E6: BURAPHA AG | F6: 46153 | G6: 31.78 | H6: paid (date) | I6: 46063 | J6: JDB-LAK LAK 704000 [Deposit to bank On 2-2- 2026.xlsx / Sheet7] | K6: Check date | L6: CR file JDB 02/02/2026 LAK 704,000. Amount OK but invoice date 11/05/2026 is after deposit 02/02/2026: verify.
A7: B0010 | B7: Burapha Agro Forestry | C7: 6138417 | D7: 27397 | E7: BURAPHAAGR | F7: 46287 | G7: 85.8 | H7: paid (date) | I7: 46304 | J7: TT BCEL-LAK 1,934,790 (= USD 85.80 @22,550) deposit 09/10/26 | K7: Matched | L7: MATCHED Kitty CR email 22/10 (mail 590). TT BCEL 1,934,790 LAK = $85.80 @22,550. Still open in Autoline: Finance post receipt.
A8: P0009 | B8: Phubia Mining | C8: 6132877 | D8: 25764 | E8: PO#4500542886 | F8: 46139 | G8: 216.88 | H8: paid (seen) | J8: àºà»àº²àºà»àº¥à»àº§ | K8: Need CR no. | L8: Paid per AR comment 21/10 (Phubia 42-inv batch, $23,766.86, ql_kb #2434). No CR number in system: need Kitty CR email. Still open in Autoline: Finance post receipts.
A9: P0009 | B9: Phubia Mining | C9: 6133353 | D9: 25812 | E9: PO#4500548812 | F9: 46153 | G9: 863 | H9: paid (seen) | J9: àºà»àº²àºà»àº¥à»àº§ | K9: Need CR no. | L9: Paid per AR comment 21/10 (Phubia 42-inv batch, $23,766.86, ql_kb #2434). No CR number in system: need Kitty CR email. Still open in Autoline: Finance post receipts.
A10: P0009 | B10: Phubia Mining | C10: 6133354 | D10: 25934 | E10: PO# 4500550066 | F10: 46153 | G10: 340 | H10: paid (seen) | J10: àºà»àº²àºà»àº¥à»àº§ | K10: Need CR no. | L10: Paid per AR comment 21/10 (Phubia 42-inv batch, $23,766.86, ql_kb #2434). No CR number in system: need Kitty CR email. Still open in Autoline: Finance post receipts.
A11: P0009 | B11: Phubia Mining | C11: 6133364 | D11: 25935 | E11: PO# 4500550066 | F11: 46153 | G11: 340 | H11: paid (seen) | J11: àºà»àº²àºà»àº¥à»àº§ | K11: Need CR no. | L11: Paid per AR comment 21/10 (Phubia 42-inv batch, $23,766.86, ql_kb #2434). No CR number in system: need Kitty CR email. Still open in Autoline: Finance post receipts.
A12: P0009 | B12: Phubia Mining | C12: 6133627 | D12: 25960 | E12: PO#4500548369 | F12: 46160 | G12: 2469.91 | H12: paid (seen) | J12: àºà»àº²àºà»àº¥à»àº§ | K12: Need CR no. | L12: Paid per AR comment 21/10 (Phubia 42-inv batch, $23,766.86, ql_kb #2434). No CR number in system: need Kitty CR email. Still open in Autoline: Finance post receipts.
A13: P0009 | B13: Phubia Mining | C13: 6133628 | D13: 25959 | E13: PO#4500548178 | F13: 46160 | G13: 300 | H13: paid (seen) | J13: àºà»àº²àºà»àº¥à»àº§ | K13: Need CR no. | L13: Paid per AR comment 21/10 (Phubia 42-inv batch, $23,766.86, ql_kb #2434). No CR number in system: need Kitty CR email. Still open in Autoline: Finance post receipts.
A14: P0009 | B14: Phubia Mining | C14: 6133629 | D14: 25958 | E14: PO#4500548178 | F14: 46160 | G14: 138.4 | H14: paid (seen) | J14: àºà»àº²àºà»àº¥à»àº§ | K14: Need CR no. | L14: Paid per AR comment 21/10 (Phubia 42-inv batch, $23,766.86, ql_kb #2434). No CR number in system: need Kitty CR email. Still open in Autoline: Finance post receipts.
A15: P0009 | B15: Phubia Mining | C15: 6133631 | D15: 25926 | E15: PO#4500548369 | F15: 46160 | G15: 211.81 | H15: paid (seen) | J15: àºà»àº²àºà»àº¥à»àº§ | K15: Need CR no. | L15: Paid per AR comment 21/10 (Phubia 42-inv batch, $23,766.86, ql_kb #2434). No CR number in system: need Kitty CR email. Still open in Autoline: Finance post receipts.
A16: P0009 | B16: Phubia Mining | C16: 6133632 | D16: 25949 | E16: PO#4500548369 | F16: 46160 | G16: 1129.76 | H16: paid (seen) | J16: àºà»àº²àºà»àº¥à»àº§ | K16: Need CR no. | L16: Paid per AR comment 21/10 (Phubia 42-inv batch, $23,766.86, ql_kb #2434). No CR number in system: need Kitty CR email. Still open in Autoline: Finance post receipts.
A17: P0009 | B17: Phubia Mining | C17: 6133690 | D17: 26118 | E17: PO#4500548178 | F17: 46162 | G17: 139.78 | H17: paid (seen) | J17: àºà»àº²àºà»àº¥à»àº§ | K17: Need CR no. | L17: Paid per AR comment 21/10 (Phubia 42-inv batch, $23,766.86, ql_kb #2434). No CR number in system: need Kitty CR email. Still open in Autoline: Finance post receipts.
A18: P0009 | B18: Phubia Mining | C18: 6134020 | D18: 25927 | E18: PO#4500548178 | F18: 46170 | G18: 485.13 | H18: paid (seen) | J18: àºà»àº²àºà»àº¥à»àº§ | K18: Need CR no. | L18: Paid per AR comment 21/10 (Phubia 42-inv batch, $23,766.86, ql_kb #2434). No CR number in system: need Kitty CR email. Still open in Autoline: Finance post receipts.
A19: P0009 | B19: Phubia Mining | C19: 6135236 | D19: 26138 | E19: PO#4500553976 | F19: 46198 | G19: 1068.45 | H19: paid (seen) | J19: àºà»àº²àºà»àº¥à»àº§ | K19: Need CR no. | L19: Paid per AR comment 21/10 (Phubia 42-inv batch, $23,766.86, ql_kb #2434). No CR number in system: need Kitty CR email. Still open in Autoline: Finance post receipts.
... A49: P0009 | B49: Phubia Mining | C49: 6138360 | D49: 27158 | E49: PO#4500570972 | F49: 46284 | G49: 711.31 | H49: paid (seen) | J49: àºà»àº²àºà»àº¥à»àº§ | K49: Need CR no. | L49: Paid per AR comment 21/10 (Phubia 42-inv batch, $23,766.86, ql_kb #2434). No CR number in system: need Kitty CR email. Still open in Autoline: Finance post receipts.
